2024-09-14 12:28:45,058 - logs - INFO - Docker Swarm is already initialized.
2024-09-14 12:29:06,626 - logs - ERROR - Error: Error response from daemon: This node is not a swarm manager. Use "docker swarm init" or "docker swarm join" to connect this node to swarm and try again.
2024-09-14 12:29:06,627 - logs - ERROR - Traceback: Traceback (most recent call last):
  File "/home/gyuri/Docking/DockerManager/swarm.py", line 12, in run_command
    result = subprocess.run(command, capture_output=True, text=True, check=True)
             ^^^^^^^^^^^^^^^^^^^^^^^^^^^^^^^^^^^^^^^^^^^^^^^^^^^^^^^^^^^^^^^^^^^
  File "/usr/lib/python3.12/subprocess.py", line 571, in run
    raise CalledProcessError(retcode, process.args,
subprocess.CalledProcessError: Command '['docker', 'service', 'create', '--name', 'arch', 'archlinux:latest']' returned non-zero exit status 1.

2024-09-14 12:29:06,627 - logs - INFO - Service 'arch' deployed.
2024-09-14 12:29:06,627 - logs - INFO - Error: Error response from daemon: This node is not a swarm manager. Use "docker swarm init" or "docker swarm join" to connect this node to swarm and try again.
2024-09-14 12:31:07,080 - logs - INFO - Docker Swarm manager status confirmed.
2024-09-14 12:31:32,971 - logs - INFO - Docker Swarm manager status confirmed.
2024-09-14 12:31:32,985 - logs - ERROR - Error: arch: invalid replicas value archlinux:latest: strconv.ParseUint: parsing "archlinux:latest": invalid syntax

2024-09-14 12:31:32,987 - logs - ERROR - Traceback: Traceback (most recent call last):
  File "/home/gyuri/Docking/DockerManager/swarm.py", line 13, in run_command
    result = subprocess.run(command, capture_output=True, text=True, check=True)
             ^^^^^^^^^^^^^^^^^^^^^^^^^^^^^^^^^^^^^^^^^^^^^^^^^^^^^^^^^^^^^^^^^^^
  File "/usr/lib/python3.12/subprocess.py", line 571, in run
    raise CalledProcessError(retcode, process.args,
subprocess.CalledProcessError: Command '['docker', 'service', 'scale', 'arch=archlinux:latest']' returned non-zero exit status 1.

2024-09-14 12:31:32,987 - logs - INFO - Service 'arch' scaled to archlinux:latest replicas.
2024-09-14 12:31:32,987 - logs - INFO - Error: arch: invalid replicas value archlinux:latest: strconv.ParseUint: parsing "archlinux:latest": invalid syntax

2024-09-14 12:33:20,639 - logs - ERROR - Error: Error response from daemon: This node is not a swarm manager. Use "docker swarm init" or "docker swarm join" to connect this node to swarm and try again.

2024-09-14 12:33:20,640 - logs - ERROR - Traceback: Traceback (most recent call last):
  File "/home/gyuri/Docking/DockerManager/swarm.py", line 13, in run_command
    result = subprocess.run(command, capture_output=True, text=True, check=True)
             ^^^^^^^^^^^^^^^^^^^^^^^^^^^^^^^^^^^^^^^^^^^^^^^^^^^^^^^^^^^^^^^^^^^
  File "/usr/lib/python3.12/subprocess.py", line 571, in run
    raise CalledProcessError(retcode, process.args,
subprocess.CalledProcessError: Command '['docker', 'service', 'create', '--name', 'arch', 'archlinux:latest']' returned non-zero exit status 1.

2024-09-14 12:33:20,641 - logs - INFO - Service 'arch' deployed using image 'archlinux:latest'.
2024-09-14 12:33:20,641 - logs - INFO - Error: Error response from daemon: This node is not a swarm manager. Use "docker swarm init" or "docker swarm join" to connect this node to swarm and try again.

2024-09-14 12:34:13,583 - logs - INFO - Docker Swarm manager status confirmed.
2024-09-14 12:34:34,152 - logs - ERROR - Command failed with return code 1: Error response from daemon: This node is not a swarm manager. Use "docker swarm init" or "docker swarm join" to connect this node to swarm and try again.

2024-09-14 12:34:34,154 - logs - ERROR - Traceback: Traceback (most recent call last):
  File "/home/gyuri/Docking/DockerManager/swarm.py", line 13, in run_command
    result = subprocess.run(command, capture_output=True, text=True, check=True)
             ^^^^^^^^^^^^^^^^^^^^^^^^^^^^^^^^^^^^^^^^^^^^^^^^^^^^^^^^^^^^^^^^^^^
  File "/usr/lib/python3.12/subprocess.py", line 571, in run
    raise CalledProcessError(retcode, process.args,
subprocess.CalledProcessError: Command '['docker', 'service', 'create', '--name', 'arcs', 'archlinux:latest']' returned non-zero exit status 1.

2024-09-14 12:34:34,154 - logs - INFO - Service 'arcs' deployed using image 'archlinux:latest'.
2024-09-14 12:34:34,154 - logs - INFO - Error: Error response from daemon: This node is not a swarm manager. Use "docker swarm init" or "docker swarm join" to connect this node to swarm and try again.

2024-09-14 12:36:13,979 - logs - INFO - Docker Swarm initialized successfully.
2024-09-14 12:36:13,979 - logs - INFO - Swarm initialized: current node (w7hf0663xo14q4wibbrq5z317) is now a manager.

To add a worker to this swarm, run the following command:

    docker swarm join --token SWMTKN-1-3unmo5q2c2x0760waalnnrds4gbhffyj8usbshhtvf89p4vnys-7i4fi76chczhwf00oxrsa1sh1 192.168.1.9:2377

To add a manager to this swarm, run 'docker swarm join-token manager' and follow the instructions.


2024-09-14 12:36:31,418 - logs - INFO - Docker Swarm manager status confirmed.
2024-09-14 12:36:31,442 - logs - INFO - Listed Swarm nodes.
2024-09-14 12:37:18,374 - logs - INFO - Docker Swarm manager status confirmed.
2024-09-14 12:37:19,115 - logs - INFO - Node left the Swarm successfully.
2024-09-14 12:37:19,115 - logs - INFO - Node left the swarm.

2024-09-14 12:39:42,704 - logs - INFO - Docker Swarm manager status confirmed.
2024-09-14 12:39:42,721 - logs - ERROR - Command failed with return code 1: Error response from daemon: This node is not a swarm manager. Use "docker swarm init" or "docker swarm join" to connect this node to swarm and try again.

2024-09-14 12:39:42,722 - logs - ERROR - Traceback: Traceback (most recent call last):
  File "/home/gyuri/Docking/DockerManager/swarm.py", line 13, in run_command
    result = subprocess.run(command, capture_output=True, text=True, check=True)
             ^^^^^^^^^^^^^^^^^^^^^^^^^^^^^^^^^^^^^^^^^^^^^^^^^^^^^^^^^^^^^^^^^^^
  File "/usr/lib/python3.12/subprocess.py", line 571, in run
    raise CalledProcessError(retcode, process.args,
subprocess.CalledProcessError: Command '['docker', 'node', 'ls']' returned non-zero exit status 1.

2024-09-14 12:39:42,722 - logs - INFO - Listed Swarm nodes.
2024-09-14 12:39:48,524 - logs - INFO - Docker Swarm initialized successfully.
2024-09-14 12:39:48,524 - logs - INFO - Swarm initialized: current node (allvl3dil1p6y94wep6lud48n) is now a manager.

To add a worker to this swarm, run the following command:

    docker swarm join --token SWMTKN-1-5jffezx8c69frxjj4r4nn4noe1n1r3lg3x80kst07ziwxypwjg-9fxvz62sonreqqp477hwd41k0 192.168.1.9:2377

To add a manager to this swarm, run 'docker swarm join-token manager' and follow the instructions.


2024-09-14 12:39:53,487 - logs - INFO - Docker Swarm manager status confirmed.
2024-09-14 12:39:53,512 - logs - INFO - Listed Swarm nodes.
2024-09-14 12:40:56,346 - logs - ERROR - Command failed with return code 1: Error response from daemon: This node is already part of a swarm. Use "docker swarm leave" to leave this swarm and join another one.

2024-09-14 12:40:56,348 - logs - ERROR - Traceback: Traceback (most recent call last):
  File "/home/gyuri/Docking/DockerManager/swarm.py", line 13, in run_command
    result = subprocess.run(command, capture_output=True, text=True, check=True)
             ^^^^^^^^^^^^^^^^^^^^^^^^^^^^^^^^^^^^^^^^^^^^^^^^^^^^^^^^^^^^^^^^^^^
  File "/usr/lib/python3.12/subprocess.py", line 571, in run
    raise CalledProcessError(retcode, process.args,
subprocess.CalledProcessError: Command '['docker', 'swarm', 'init']' returned non-zero exit status 1.

2024-09-14 12:40:56,348 - logs - INFO - Docker Swarm initialized successfully.
2024-09-14 12:40:56,348 - logs - INFO - Error: Error response from daemon: This node is already part of a swarm. Use "docker swarm leave" to leave this swarm and join another one.

2024-09-14 12:40:59,694 - logs - INFO - Docker Swarm manager status confirmed.
2024-09-14 12:41:00,008 - logs - INFO - Node left the Swarm successfully.
2024-09-14 12:41:00,008 - logs - INFO - Node left the swarm.

2024-09-14 12:41:02,606 - logs - INFO - Docker Swarm initialized successfully.
2024-09-14 12:41:02,606 - logs - INFO - Swarm initialized: current node (v98fg5cuc5qhf0oa2zw5im2dw) is now a manager.

To add a worker to this swarm, run the following command:

    docker swarm join --token SWMTKN-1-2477tpjmv26j4mxaveefwzzf7327s2rmk1g7srl3j4bot4jfgz-8i2c24rf6y0d4fcjv7g68577r 192.168.1.9:2377

To add a manager to this swarm, run 'docker swarm join-token manager' and follow the instructions.


2024-09-14 12:41:04,064 - logs - INFO - Docker Swarm manager status confirmed.
2024-09-14 12:41:04,088 - logs - INFO - Listed Swarm nodes.
2024-09-14 12:43:00,509 - logs - INFO - Docker Swarm manager status confirmed.
2024-09-14 12:43:00,867 - logs - INFO - Node left the Swarm successfully.
2024-09-14 12:43:00,867 - logs - INFO - Node left the swarm.

2024-09-14 12:46:22,214 - logs - INFO - Docker Swarm initialized successfully.
2024-09-14 12:46:22,214 - logs - INFO - Swarm initialized: current node (oey2vlul0ijv05ig37cabk74c) is now a manager.

To add a worker to this swarm, run the following command:

    docker swarm join --token SWMTKN-1-4fe7v4fks91dmwl3b9u4kci8q8k53eo5ygaessdq1a1bscnw4j-927zirt72feitny7mn9b8s9z1 192.168.1.9:2377

To add a manager to this swarm, run 'docker swarm join-token manager' and follow the instructions.


2024-09-14 12:47:58,213 - logs - INFO - Docker Swarm manager status confirmed.
2024-09-14 12:48:57,903 - logs - INFO - Docker Swarm manager status confirmed.
2024-09-14 12:48:58,338 - logs - INFO - Node left the Swarm successfully.
2024-09-14 12:48:58,338 - logs - INFO - Node left the swarm.

2024-09-14 12:49:02,699 - logs - INFO - Docker Swarm manager status confirmed.
2024-09-14 12:49:02,713 - logs - ERROR - Command failed with return code 1: Error response from daemon: This node is not a swarm manager. Use "docker swarm init" or "docker swarm join" to connect this node to swarm and try again.

2024-09-14 12:49:02,714 - logs - ERROR - Traceback: Traceback (most recent call last):
  File "/home/gyuri/Docking/DockerManager/swarm.py", line 13, in run_command
    result = subprocess.run(command, capture_output=True, text=True, check=True)
             ^^^^^^^^^^^^^^^^^^^^^^^^^^^^^^^^^^^^^^^^^^^^^^^^^^^^^^^^^^^^^^^^^^^
  File "/usr/lib/python3.12/subprocess.py", line 571, in run
    raise CalledProcessError(retcode, process.args,
subprocess.CalledProcessError: Command '['docker', 'node', 'ls']' returned non-zero exit status 1.

2024-09-14 12:49:02,714 - logs - INFO - Listed Swarm nodes.
2024-09-14 12:49:04,899 - logs - INFO - Docker Swarm initialized successfully.
2024-09-14 12:49:04,899 - logs - INFO - Swarm initialized: current node (3qb63azx5l01v1nugu8dkh3wy) is now a manager.

To add a worker to this swarm, run the following command:

    docker swarm join --token SWMTKN-1-29piza3cla8p2tj8mmk1elh30heynnqgfv5hzjfcatb0b4juga-e95wrqhsz11m15bahebhebdsg 192.168.1.9:2377

To add a manager to this swarm, run 'docker swarm join-token manager' and follow the instructions.


2024-09-14 12:51:16,127 - logs - INFO - Docker Swarm manager status confirmed.
2024-09-14 12:51:28,798 - logs - INFO - Listing all containers.
2024-09-14 12:51:45,318 - logs - INFO - Docker Swarm manager status confirmed.
2024-09-14 12:51:45,531 - logs - ERROR - Command failed with return code 1: arcs: Error response from daemon: This node is not a swarm manager. Use "docker swarm init" or "docker swarm join" to connect this node to swarm and try again.

2024-09-14 12:51:45,533 - logs - ERROR - Traceback: Traceback (most recent call last):
  File "/home/gyuri/Docking/DockerManager/swarm.py", line 13, in run_command
    result = subprocess.run(command, capture_output=True, text=True, check=True)
             ^^^^^^^^^^^^^^^^^^^^^^^^^^^^^^^^^^^^^^^^^^^^^^^^^^^^^^^^^^^^^^^^^^^
  File "/usr/lib/python3.12/subprocess.py", line 571, in run
    raise CalledProcessError(retcode, process.args,
subprocess.CalledProcessError: Command '['docker', 'service', 'scale', 'arcs=5']' returned non-zero exit status 1.

2024-09-14 12:51:45,533 - logs - INFO - Service 'arcs' scaled to 5 replicas.
2024-09-14 12:51:45,533 - logs - INFO - Error: arcs: Error response from daemon: This node is not a swarm manager. Use "docker swarm init" or "docker swarm join" to connect this node to swarm and try again.

2024-09-14 12:51:45,565 - logs - ERROR - Command failed with return code 1: Error response from daemon: This node is not a swarm manager. Use "docker swarm init" or "docker swarm join" to connect this node to swarm and try again.

2024-09-14 12:51:45,565 - logs - ERROR - Traceback: Traceback (most recent call last):
  File "/home/gyuri/Docking/DockerManager/swarm.py", line 13, in run_command
    result = subprocess.run(command, capture_output=True, text=True, check=True)
             ^^^^^^^^^^^^^^^^^^^^^^^^^^^^^^^^^^^^^^^^^^^^^^^^^^^^^^^^^^^^^^^^^^^
  File "/usr/lib/python3.12/subprocess.py", line 571, in run
    raise CalledProcessError(retcode, process.args,
subprocess.CalledProcessError: Command '['docker', 'service', 'create', '--name', 'arcs', 'archlinux:latest']' returned non-zero exit status 1.

2024-09-14 12:51:45,566 - logs - INFO - Service 'arcs' deployed with image 'archlinux:latest'.
2024-09-14 12:51:45,950 - logs - INFO - Node left the Swarm successfully.
2024-09-14 12:51:45,950 - logs - INFO - Node left the swarm.

2024-09-14 13:14:31,342 - logs - INFO - Listing all containers.
2024-09-14 13:14:35,503 - logs - INFO - Prompting user to create a new container.
2024-09-14 13:19:57,974 - werkzeug - INFO - [31m[1mWARNING: This is a development server. Do not use it in a production deployment. Use a production WSGI server instead.[0m
 * Running on http://127.0.0.1:5000
2024-09-14 13:19:57,974 - werkzeug - INFO - [33mPress CTRL+C to quit[0m
2024-09-14 13:20:08,912 - werkzeug - INFO - 127.0.0.1 - - [14/Sep/2024 13:20:08] "GET / HTTP/1.1" 200 -
2024-09-14 13:20:08,948 - werkzeug - INFO - 127.0.0.1 - - [14/Sep/2024 13:20:08] "GET /static/styles.css HTTP/1.1" 200 -
2024-09-14 13:20:08,995 - werkzeug - INFO - 127.0.0.1 - - [14/Sep/2024 13:20:08] "[33mGET /favicon.ico HTTP/1.1[0m" 404 -
2024-09-14 13:21:51,284 - werkzeug - INFO - [31m[1mWARNING: This is a development server. Do not use it in a production deployment. Use a production WSGI server instead.[0m
 * Running on http://127.0.0.1:5000
2024-09-14 13:21:51,284 - werkzeug - INFO - [33mPress CTRL+C to quit[0m
2024-09-14 13:22:13,196 - werkzeug - INFO - [31m[1mWARNING: This is a development server. Do not use it in a production deployment. Use a production WSGI server instead.[0m
 * Running on http://127.0.0.1:5000
2024-09-14 13:22:13,196 - werkzeug - INFO - [33mPress CTRL+C to quit[0m
2024-09-14 13:23:02,718 - werkzeug - INFO - [31m[1mWARNING: This is a development server. Do not use it in a production deployment. Use a production WSGI server instead.[0m
 * Running on http://127.0.0.1:5000
2024-09-14 13:23:02,718 - werkzeug - INFO - [33mPress CTRL+C to quit[0m
2024-09-14 13:23:05,838 - werkzeug - INFO - 127.0.0.1 - - [14/Sep/2024 13:23:05] "GET / HTTP/1.1" 200 -
2024-09-14 13:23:05,909 - werkzeug - INFO - 127.0.0.1 - - [14/Sep/2024 13:23:05] "[36mGET /static/styles.css HTTP/1.1[0m" 304 -
2024-09-14 13:23:06,853 - werkzeug - INFO - 127.0.0.1 - - [14/Sep/2024 13:23:06] "GET /volume_network_info HTTP/1.1" 200 -
2024-09-14 13:23:06,873 - werkzeug - INFO - 127.0.0.1 - - [14/Sep/2024 13:23:06] "[36mGET /static/styles.css HTTP/1.1[0m" 304 -
2024-09-14 13:23:07,698 - werkzeug - INFO - 127.0.0.1 - - [14/Sep/2024 13:23:07] "GET /interactive_visualizations HTTP/1.1" 200 -
2024-09-14 13:23:07,717 - werkzeug - INFO - 127.0.0.1 - - [14/Sep/2024 13:23:07] "[36mGET /static/styles.css HTTP/1.1[0m" 304 -
2024-09-14 13:23:09,221 - werkzeug - INFO - 127.0.0.1 - - [14/Sep/2024 13:23:09] "GET /volume_network_info HTTP/1.1" 200 -
2024-09-14 13:23:09,244 - werkzeug - INFO - 127.0.0.1 - - [14/Sep/2024 13:23:09] "[36mGET /static/styles.css HTTP/1.1[0m" 304 -
2024-09-14 13:23:11,039 - werkzeug - INFO - 127.0.0.1 - - [14/Sep/2024 13:23:11] "POST /volume_network_info HTTP/1.1" 200 -
2024-09-14 13:23:11,057 - werkzeug - INFO - 127.0.0.1 - - [14/Sep/2024 13:23:11] "[36mGET /static/styles.css HTTP/1.1[0m" 304 -
2024-09-14 13:23:15,708 - werkzeug - INFO - 127.0.0.1 - - [14/Sep/2024 13:23:15] "GET /images HTTP/1.1" 200 -
2024-09-14 13:23:15,731 - werkzeug - INFO - 127.0.0.1 - - [14/Sep/2024 13:23:15] "[36mGET /static/styles.css HTTP/1.1[0m" 304 -
2024-09-14 13:23:17,309 - werkzeug - INFO - 127.0.0.1 - - [14/Sep/2024 13:23:17] "[35m[1mPOST /image HTTP/1.1[0m" 500 -
2024-09-14 13:24:49,866 - werkzeug - INFO - [31m[1mWARNING: This is a development server. Do not use it in a production deployment. Use a production WSGI server instead.[0m
 * Running on http://127.0.0.1:5000
2024-09-14 13:24:49,866 - werkzeug - INFO - [33mPress CTRL+C to quit[0m
2024-09-14 13:24:59,373 - werkzeug - INFO - 127.0.0.1 - - [14/Sep/2024 13:24:59] "GET / HTTP/1.1" 200 -
2024-09-14 13:24:59,411 - werkzeug - INFO - 127.0.0.1 - - [14/Sep/2024 13:24:59] "[36mGET /static/styles.css HTTP/1.1[0m" 304 -
2024-09-14 13:25:19,925 - logs - INFO - Listing all images.
2024-09-14 13:25:21,381 - logs - INFO - Removing image with ID: sha256:edbfe74c41f8a3501ce542e137cf28ea04dd03e6df8c9d66519b6ad761c2598a
2024-09-14 13:25:21,621 - logs - INFO - Image 'sha256:edbfe74c41f8a3501ce542e137cf28ea04dd03e6df8c9d66519b6ad761c2598a' removed successfully.
2024-09-14 13:25:21,621 - logs - INFO - Listing all images.
2024-09-14 13:25:22,614 - logs - INFO - Removing image with ID: sha256:88e34eb59b71012351582a045b4fff0f634e7419658a7110e2f83fe92a1c9c9a
2024-09-14 13:25:23,143 - logs - INFO - Image 'sha256:88e34eb59b71012351582a045b4fff0f634e7419658a7110e2f83fe92a1c9c9a' removed successfully.
2024-09-14 13:25:23,144 - logs - INFO - Listing all images.
2024-09-14 13:26:12,343 - werkzeug - INFO - 127.0.0.1 - - [14/Sep/2024 13:26:12] "GET / HTTP/1.1" 200 -
2024-09-14 13:26:12,371 - werkzeug - INFO - 127.0.0.1 - - [14/Sep/2024 13:26:12] "[36mGET /static/styles.css HTTP/1.1[0m" 304 -
2024-09-14 13:26:13,117 - werkzeug - INFO - 127.0.0.1 - - [14/Sep/2024 13:26:13] "GET / HTTP/1.1" 200 -
2024-09-14 13:26:13,140 - werkzeug - INFO - 127.0.0.1 - - [14/Sep/2024 13:26:13] "[36mGET /static/styles.css HTTP/1.1[0m" 304 -
2024-09-14 13:26:13,461 - werkzeug - INFO - 127.0.0.1 - - [14/Sep/2024 13:26:13] "GET / HTTP/1.1" 200 -
2024-09-14 13:26:13,487 - werkzeug - INFO - 127.0.0.1 - - [14/Sep/2024 13:26:13] "[36mGET /static/styles.css HTTP/1.1[0m" 304 -
2024-09-14 13:26:13,741 - werkzeug - INFO - 127.0.0.1 - - [14/Sep/2024 13:26:13] "GET / HTTP/1.1" 200 -
2024-09-14 13:26:13,764 - werkzeug - INFO - 127.0.0.1 - - [14/Sep/2024 13:26:13] "[36mGET /static/styles.css HTTP/1.1[0m" 304 -
2024-09-14 13:26:14,071 - werkzeug - INFO - 127.0.0.1 - - [14/Sep/2024 13:26:14] "GET / HTTP/1.1" 200 -
2024-09-14 13:26:14,097 - werkzeug - INFO - 127.0.0.1 - - [14/Sep/2024 13:26:14] "[36mGET /static/styles.css HTTP/1.1[0m" 304 -
2024-09-14 13:26:14,302 - werkzeug - INFO - 127.0.0.1 - - [14/Sep/2024 13:26:14] "GET / HTTP/1.1" 200 -
2024-09-14 13:26:14,330 - werkzeug - INFO - 127.0.0.1 - - [14/Sep/2024 13:26:14] "[36mGET /static/styles.css HTTP/1.1[0m" 304 -
2024-09-14 13:26:14,558 - werkzeug - INFO - 127.0.0.1 - - [14/Sep/2024 13:26:14] "GET / HTTP/1.1" 200 -
2024-09-14 13:26:14,586 - werkzeug - INFO - 127.0.0.1 - - [14/Sep/2024 13:26:14] "[36mGET /static/styles.css HTTP/1.1[0m" 304 -
2024-09-14 13:26:14,832 - werkzeug - INFO - 127.0.0.1 - - [14/Sep/2024 13:26:14] "GET / HTTP/1.1" 200 -
2024-09-14 13:26:14,871 - werkzeug - INFO - 127.0.0.1 - - [14/Sep/2024 13:26:14] "[36mGET /static/styles.css HTTP/1.1[0m" 304 -
2024-09-14 13:26:15,051 - werkzeug - INFO - 127.0.0.1 - - [14/Sep/2024 13:26:15] "GET / HTTP/1.1" 200 -
2024-09-14 13:26:15,084 - werkzeug - INFO - 127.0.0.1 - - [14/Sep/2024 13:26:15] "[36mGET /static/styles.css HTTP/1.1[0m" 304 -
2024-09-14 13:26:15,269 - werkzeug - INFO - 127.0.0.1 - - [14/Sep/2024 13:26:15] "GET / HTTP/1.1" 200 -
2024-09-14 13:26:15,297 - werkzeug - INFO - 127.0.0.1 - - [14/Sep/2024 13:26:15] "[36mGET /static/styles.css HTTP/1.1[0m" 304 -
2024-09-14 13:26:15,470 - werkzeug - INFO - 127.0.0.1 - - [14/Sep/2024 13:26:15] "GET / HTTP/1.1" 200 -
2024-09-14 13:26:15,490 - werkzeug - INFO - 127.0.0.1 - - [14/Sep/2024 13:26:15] "[36mGET /static/styles.css HTTP/1.1[0m" 304 -
2024-09-14 13:26:15,678 - werkzeug - INFO - 127.0.0.1 - - [14/Sep/2024 13:26:15] "GET / HTTP/1.1" 200 -
2024-09-14 13:26:15,706 - werkzeug - INFO - 127.0.0.1 - - [14/Sep/2024 13:26:15] "[36mGET /static/styles.css HTTP/1.1[0m" 304 -
2024-09-14 13:26:15,869 - werkzeug - INFO - 127.0.0.1 - - [14/Sep/2024 13:26:15] "GET / HTTP/1.1" 200 -
2024-09-14 13:26:15,890 - werkzeug - INFO - 127.0.0.1 - - [14/Sep/2024 13:26:15] "[36mGET /static/styles.css HTTP/1.1[0m" 304 -
2024-09-14 13:26:16,078 - werkzeug - INFO - 127.0.0.1 - - [14/Sep/2024 13:26:16] "GET / HTTP/1.1" 200 -
2024-09-14 13:26:16,102 - werkzeug - INFO - 127.0.0.1 - - [14/Sep/2024 13:26:16] "[36mGET /static/styles.css HTTP/1.1[0m" 304 -
2024-09-14 13:26:16,325 - werkzeug - INFO - 127.0.0.1 - - [14/Sep/2024 13:26:16] "GET / HTTP/1.1" 200 -
2024-09-14 13:26:16,383 - werkzeug - INFO - 127.0.0.1 - - [14/Sep/2024 13:26:16] "[36mGET /static/styles.css HTTP/1.1[0m" 304 -
2024-09-14 13:28:42,376 - werkzeug - INFO - [31m[1mWARNING: This is a development server. Do not use it in a production deployment. Use a production WSGI server instead.[0m
 * Running on http://127.0.0.1:5000
2024-09-14 13:28:42,376 - werkzeug - INFO - [33mPress CTRL+C to quit[0m
2024-09-14 13:29:53,720 - werkzeug - INFO - [31m[1mWARNING: This is a development server. Do not use it in a production deployment. Use a production WSGI server instead.[0m
 * Running on http://127.0.0.1:5000
2024-09-14 13:29:53,721 - werkzeug - INFO - [33mPress CTRL+C to quit[0m
2024-09-14 13:31:19,035 - werkzeug - INFO - [31m[1mWARNING: This is a development server. Do not use it in a production deployment. Use a production WSGI server instead.[0m
 * Running on http://127.0.0.1:5000
2024-09-14 13:31:19,036 - werkzeug - INFO - [33mPress CTRL+C to quit[0m
2024-09-14 13:31:35,612 - werkzeug - INFO - [31m[1mWARNING: This is a development server. Do not use it in a production deployment. Use a production WSGI server instead.[0m
 * Running on http://127.0.0.1:5000
2024-09-14 13:31:35,612 - werkzeug - INFO - [33mPress CTRL+C to quit[0m
2024-09-14 13:31:49,650 - werkzeug - INFO - 127.0.0.1 - - [14/Sep/2024 13:31:49] "GET / HTTP/1.1" 200 -
2024-09-14 13:31:49,683 - werkzeug - INFO - 127.0.0.1 - - [14/Sep/2024 13:31:49] "[36mGET /static/styles.css HTTP/1.1[0m" 304 -
2024-09-14 13:31:56,352 - werkzeug - INFO - 127.0.0.1 - - [14/Sep/2024 13:31:56] "[31m[1mGET /shutdown HTTP/1.1[0m" 405 -
2024-09-14 13:36:25,887 - logs - ERROR - Error shutting down server: HTTPConnectionPool(host='localhost', port=5000): Max retries exceeded with url: /shutdown (Caused by NewConnectionError('<urllib3.connection.HTTPConnection object at 0x7a39e7984140>: Failed to establish a new connection: [Errno 111] Connection refused'))
2024-09-14 13:36:25,930 - logs - ERROR - Traceback: Traceback (most recent call last):
  File "/home/gyuri/venv/lib/python3.12/site-packages/urllib3/connection.py", line 196, in _new_conn
    sock = connection.create_connection(
           ^^^^^^^^^^^^^^^^^^^^^^^^^^^^^
  File "/home/gyuri/venv/lib/python3.12/site-packages/urllib3/util/connection.py", line 85, in create_connection
    raise err
  File "/home/gyuri/venv/lib/python3.12/site-packages/urllib3/util/connection.py", line 73, in create_connection
    sock.connect(sa)
ConnectionRefusedError: [Errno 111] Connection refused

The above exception was the direct cause of the following exception:

Traceback (most recent call last):
  File "/home/gyuri/venv/lib/python3.12/site-packages/urllib3/connectionpool.py", line 789, in urlopen
    response = self._make_request(
               ^^^^^^^^^^^^^^^^^^^
  File "/home/gyuri/venv/lib/python3.12/site-packages/urllib3/connectionpool.py", line 495, in _make_request
    conn.request(
  File "/home/gyuri/venv/lib/python3.12/site-packages/urllib3/connection.py", line 398, in request
    self.endheaders()
  File "/usr/lib/python3.12/http/client.py", line 1331, in endheaders
    self._send_output(message_body, encode_chunked=encode_chunked)
  File "/usr/lib/python3.12/http/client.py", line 1091, in _send_output
    self.send(msg)
  File "/usr/lib/python3.12/http/client.py", line 1035, in send
    self.connect()
  File "/home/gyuri/venv/lib/python3.12/site-packages/urllib3/connection.py", line 236, in connect
    self.sock = self._new_conn()
                ^^^^^^^^^^^^^^^^
  File "/home/gyuri/venv/lib/python3.12/site-packages/urllib3/connection.py", line 211, in _new_conn
    raise NewConnectionError(
urllib3.exceptions.NewConnectionError: <urllib3.connection.HTTPConnection object at 0x7a39e7984140>: Failed to establish a new connection: [Errno 111] Connection refused

The above exception was the direct cause of the following exception:

Traceback (most recent call last):
  File "/home/gyuri/venv/lib/python3.12/site-packages/requests/adapters.py", line 667, in send
    resp = conn.urlopen(
           ^^^^^^^^^^^^^
  File "/home/gyuri/venv/lib/python3.12/site-packages/urllib3/connectionpool.py", line 843, in urlopen
    retries = retries.increment(
              ^^^^^^^^^^^^^^^^^^
  File "/home/gyuri/venv/lib/python3.12/site-packages/urllib3/util/retry.py", line 519, in increment
    raise MaxRetryError(_pool, url, reason) from reason  # type: ignore[arg-type]
    ^^^^^^^^^^^^^^^^^^^^^^^^^^^^^^^^^^^^^^^^^^^^^^^^^^^
urllib3.exceptions.MaxRetryError: HTTPConnectionPool(host='localhost', port=5000): Max retries exceeded with url: /shutdown (Caused by NewConnectionError('<urllib3.connection.HTTPConnection object at 0x7a39e7984140>: Failed to establish a new connection: [Errno 111] Connection refused'))

During handling of the above exception, another exception occurred:

Traceback (most recent call last):
  File "/home/gyuri/Docking/DockerManager/Image_detailer/app.py", line 24, in stop_image_detailer
    requests.post("http://localhost:5000/shutdown")
  File "/home/gyuri/venv/lib/python3.12/site-packages/requests/api.py", line 115, in post
    return request("post", url, data=data, json=json, **kwargs)
           ^^^^^^^^^^^^^^^^^^^^^^^^^^^^^^^^^^^^^^^^^^^^^^^^^^^^
  File "/home/gyuri/venv/lib/python3.12/site-packages/requests/api.py", line 59, in request
    return session.request(method=method, url=url, **kwargs)
           ^^^^^^^^^^^^^^^^^^^^^^^^^^^^^^^^^^^^^^^^^^^^^^^^^
  File "/home/gyuri/venv/lib/python3.12/site-packages/requests/sessions.py", line 589, in request
    resp = self.send(prep, **send_kwargs)
           ^^^^^^^^^^^^^^^^^^^^^^^^^^^^^^
  File "/home/gyuri/venv/lib/python3.12/site-packages/requests/sessions.py", line 703, in send
    r = adapter.send(request, **kwargs)
        ^^^^^^^^^^^^^^^^^^^^^^^^^^^^^^^
  File "/home/gyuri/venv/lib/python3.12/site-packages/requests/adapters.py", line 700, in send
    raise ConnectionError(e, request=request)
requests.exceptions.ConnectionError: HTTPConnectionPool(host='localhost', port=5000): Max retries exceeded with url: /shutdown (Caused by NewConnectionError('<urllib3.connection.HTTPConnection object at 0x7a39e7984140>: Failed to establish a new connection: [Errno 111] Connection refused'))

2024-09-14 13:43:38,031 - logs - INFO - Server started.
2024-09-14 13:43:39,479 - logs - INFO - Server started.
2024-09-14 13:43:40,483 - logs - INFO - Server started.
2024-09-14 13:43:41,487 - logs - INFO - Server started.
2024-09-14 13:43:42,489 - logs - INFO - Server started.
2024-09-14 13:43:43,493 - logs - INFO - Server started.
2024-09-14 13:44:13,337 - logs - ERROR - Server is not running or already shut down.
2024-09-14 13:44:13,342 - logs - ERROR - Traceback: Traceback (most recent call last):
  File "/home/gyuri/venv/lib/python3.12/site-packages/urllib3/connection.py", line 196, in _new_conn
    sock = connection.create_connection(
           ^^^^^^^^^^^^^^^^^^^^^^^^^^^^^
  File "/home/gyuri/venv/lib/python3.12/site-packages/urllib3/util/connection.py", line 85, in create_connection
    raise err
  File "/home/gyuri/venv/lib/python3.12/site-packages/urllib3/util/connection.py", line 73, in create_connection
    sock.connect(sa)
ConnectionRefusedError: [Errno 111] Connection refused

The above exception was the direct cause of the following exception:

Traceback (most recent call last):
  File "/home/gyuri/venv/lib/python3.12/site-packages/urllib3/connectionpool.py", line 789, in urlopen
    response = self._make_request(
               ^^^^^^^^^^^^^^^^^^^
  File "/home/gyuri/venv/lib/python3.12/site-packages/urllib3/connectionpool.py", line 495, in _make_request
    conn.request(
  File "/home/gyuri/venv/lib/python3.12/site-packages/urllib3/connection.py", line 398, in request
    self.endheaders()
  File "/usr/lib/python3.12/http/client.py", line 1331, in endheaders
    self._send_output(message_body, encode_chunked=encode_chunked)
  File "/usr/lib/python3.12/http/client.py", line 1091, in _send_output
    self.send(msg)
  File "/usr/lib/python3.12/http/client.py", line 1035, in send
    self.connect()
  File "/home/gyuri/venv/lib/python3.12/site-packages/urllib3/connection.py", line 236, in connect
    self.sock = self._new_conn()
                ^^^^^^^^^^^^^^^^
  File "/home/gyuri/venv/lib/python3.12/site-packages/urllib3/connection.py", line 211, in _new_conn
    raise NewConnectionError(
urllib3.exceptions.NewConnectionError: <urllib3.connection.HTTPConnection object at 0x7f55fbf8c050>: Failed to establish a new connection: [Errno 111] Connection refused

The above exception was the direct cause of the following exception:

Traceback (most recent call last):
  File "/home/gyuri/venv/lib/python3.12/site-packages/requests/adapters.py", line 667, in send
    resp = conn.urlopen(
           ^^^^^^^^^^^^^
  File "/home/gyuri/venv/lib/python3.12/site-packages/urllib3/connectionpool.py", line 843, in urlopen
    retries = retries.increment(
              ^^^^^^^^^^^^^^^^^^
  File "/home/gyuri/venv/lib/python3.12/site-packages/urllib3/util/retry.py", line 519, in increment
    raise MaxRetryError(_pool, url, reason) from reason  # type: ignore[arg-type]
    ^^^^^^^^^^^^^^^^^^^^^^^^^^^^^^^^^^^^^^^^^^^^^^^^^^^
urllib3.exceptions.MaxRetryError: HTTPConnectionPool(host='localhost', port=5000): Max retries exceeded with url: /shutdown (Caused by NewConnectionError('<urllib3.connection.HTTPConnection object at 0x7f55fbf8c050>: Failed to establish a new connection: [Errno 111] Connection refused'))

During handling of the above exception, another exception occurred:

Traceback (most recent call last):
  File "/home/gyuri/Docking/DockerManager/docker_gui.py", line 299, in stop_image_detailer
    requests.post("http://localhost:5000/shutdown")
  File "/home/gyuri/venv/lib/python3.12/site-packages/requests/api.py", line 115, in post
    return request("post", url, data=data, json=json, **kwargs)
           ^^^^^^^^^^^^^^^^^^^^^^^^^^^^^^^^^^^^^^^^^^^^^^^^^^^^
  File "/home/gyuri/venv/lib/python3.12/site-packages/requests/api.py", line 59, in request
    return session.request(method=method, url=url, **kwargs)
           ^^^^^^^^^^^^^^^^^^^^^^^^^^^^^^^^^^^^^^^^^^^^^^^^^
  File "/home/gyuri/venv/lib/python3.12/site-packages/requests/sessions.py", line 589, in request
    resp = self.send(prep, **send_kwargs)
           ^^^^^^^^^^^^^^^^^^^^^^^^^^^^^^
  File "/home/gyuri/venv/lib/python3.12/site-packages/requests/sessions.py", line 703, in send
    r = adapter.send(request, **kwargs)
        ^^^^^^^^^^^^^^^^^^^^^^^^^^^^^^^
  File "/home/gyuri/venv/lib/python3.12/site-packages/requests/adapters.py", line 700, in send
    raise ConnectionError(e, request=request)
requests.exceptions.ConnectionError: HTTPConnectionPool(host='localhost', port=5000): Max retries exceeded with url: /shutdown (Caused by NewConnectionError('<urllib3.connection.HTTPConnection object at 0x7f55fbf8c050>: Failed to establish a new connection: [Errno 111] Connection refused'))

2024-09-14 13:44:13,342 - logs - INFO - Server thread joined successfully.
2024-09-14 13:44:32,936 - logs - INFO - Server started.
2024-09-14 13:44:45,426 - logs - ERROR - Server is not running or already shut down.
2024-09-14 13:44:45,429 - logs - ERROR - Traceback: Traceback (most recent call last):
  File "/home/gyuri/venv/lib/python3.12/site-packages/urllib3/connection.py", line 196, in _new_conn
    sock = connection.create_connection(
           ^^^^^^^^^^^^^^^^^^^^^^^^^^^^^
  File "/home/gyuri/venv/lib/python3.12/site-packages/urllib3/util/connection.py", line 85, in create_connection
    raise err
  File "/home/gyuri/venv/lib/python3.12/site-packages/urllib3/util/connection.py", line 73, in create_connection
    sock.connect(sa)
ConnectionRefusedError: [Errno 111] Connection refused

The above exception was the direct cause of the following exception:

Traceback (most recent call last):
  File "/home/gyuri/venv/lib/python3.12/site-packages/urllib3/connectionpool.py", line 789, in urlopen
    response = self._make_request(
               ^^^^^^^^^^^^^^^^^^^
  File "/home/gyuri/venv/lib/python3.12/site-packages/urllib3/connectionpool.py", line 495, in _make_request
    conn.request(
  File "/home/gyuri/venv/lib/python3.12/site-packages/urllib3/connection.py", line 398, in request
    self.endheaders()
  File "/usr/lib/python3.12/http/client.py", line 1331, in endheaders
    self._send_output(message_body, encode_chunked=encode_chunked)
  File "/usr/lib/python3.12/http/client.py", line 1091, in _send_output
    self.send(msg)
  File "/usr/lib/python3.12/http/client.py", line 1035, in send
    self.connect()
  File "/home/gyuri/venv/lib/python3.12/site-packages/urllib3/connection.py", line 236, in connect
    self.sock = self._new_conn()
                ^^^^^^^^^^^^^^^^
  File "/home/gyuri/venv/lib/python3.12/site-packages/urllib3/connection.py", line 211, in _new_conn
    raise NewConnectionError(
urllib3.exceptions.NewConnectionError: <urllib3.connection.HTTPConnection object at 0x77a05bf70080>: Failed to establish a new connection: [Errno 111] Connection refused

The above exception was the direct cause of the following exception:

Traceback (most recent call last):
  File "/home/gyuri/venv/lib/python3.12/site-packages/requests/adapters.py", line 667, in send
    resp = conn.urlopen(
           ^^^^^^^^^^^^^
  File "/home/gyuri/venv/lib/python3.12/site-packages/urllib3/connectionpool.py", line 843, in urlopen
    retries = retries.increment(
              ^^^^^^^^^^^^^^^^^^
  File "/home/gyuri/venv/lib/python3.12/site-packages/urllib3/util/retry.py", line 519, in increment
    raise MaxRetryError(_pool, url, reason) from reason  # type: ignore[arg-type]
    ^^^^^^^^^^^^^^^^^^^^^^^^^^^^^^^^^^^^^^^^^^^^^^^^^^^
urllib3.exceptions.MaxRetryError: HTTPConnectionPool(host='localhost', port=5000): Max retries exceeded with url: /shutdown (Caused by NewConnectionError('<urllib3.connection.HTTPConnection object at 0x77a05bf70080>: Failed to establish a new connection: [Errno 111] Connection refused'))

During handling of the above exception, another exception occurred:

Traceback (most recent call last):
  File "/home/gyuri/Docking/DockerManager/docker_gui.py", line 299, in stop_image_detailer
    requests.post("http://localhost:5000/shutdown")
  File "/home/gyuri/venv/lib/python3.12/site-packages/requests/api.py", line 115, in post
    return request("post", url, data=data, json=json, **kwargs)
           ^^^^^^^^^^^^^^^^^^^^^^^^^^^^^^^^^^^^^^^^^^^^^^^^^^^^
  File "/home/gyuri/venv/lib/python3.12/site-packages/requests/api.py", line 59, in request
    return session.request(method=method, url=url, **kwargs)
           ^^^^^^^^^^^^^^^^^^^^^^^^^^^^^^^^^^^^^^^^^^^^^^^^^
  File "/home/gyuri/venv/lib/python3.12/site-packages/requests/sessions.py", line 589, in request
    resp = self.send(prep, **send_kwargs)
           ^^^^^^^^^^^^^^^^^^^^^^^^^^^^^^
  File "/home/gyuri/venv/lib/python3.12/site-packages/requests/sessions.py", line 703, in send
    r = adapter.send(request, **kwargs)
        ^^^^^^^^^^^^^^^^^^^^^^^^^^^^^^^
  File "/home/gyuri/venv/lib/python3.12/site-packages/requests/adapters.py", line 700, in send
    raise ConnectionError(e, request=request)
requests.exceptions.ConnectionError: HTTPConnectionPool(host='localhost', port=5000): Max retries exceeded with url: /shutdown (Caused by NewConnectionError('<urllib3.connection.HTTPConnection object at 0x77a05bf70080>: Failed to establish a new connection: [Errno 111] Connection refused'))

2024-09-14 13:44:45,430 - logs - INFO - Server thread joined successfully.
2024-09-14 13:49:22,959 - logs - INFO - Server started.
2024-09-14 13:49:29,776 - logs - ERROR - Server is not running or already shut down.
2024-09-14 13:49:29,780 - logs - ERROR - Traceback: Traceback (most recent call last):
  File "/home/gyuri/venv/lib/python3.12/site-packages/urllib3/connection.py", line 196, in _new_conn
    sock = connection.create_connection(
           ^^^^^^^^^^^^^^^^^^^^^^^^^^^^^
  File "/home/gyuri/venv/lib/python3.12/site-packages/urllib3/util/connection.py", line 85, in create_connection
    raise err
  File "/home/gyuri/venv/lib/python3.12/site-packages/urllib3/util/connection.py", line 73, in create_connection
    sock.connect(sa)
ConnectionRefusedError: [Errno 111] Connection refused

The above exception was the direct cause of the following exception:

Traceback (most recent call last):
  File "/home/gyuri/venv/lib/python3.12/site-packages/urllib3/connectionpool.py", line 789, in urlopen
    response = self._make_request(
               ^^^^^^^^^^^^^^^^^^^
  File "/home/gyuri/venv/lib/python3.12/site-packages/urllib3/connectionpool.py", line 495, in _make_request
    conn.request(
  File "/home/gyuri/venv/lib/python3.12/site-packages/urllib3/connection.py", line 398, in request
    self.endheaders()
  File "/usr/lib/python3.12/http/client.py", line 1331, in endheaders
    self._send_output(message_body, encode_chunked=encode_chunked)
  File "/usr/lib/python3.12/http/client.py", line 1091, in _send_output
    self.send(msg)
  File "/usr/lib/python3.12/http/client.py", line 1035, in send
    self.connect()
  File "/home/gyuri/venv/lib/python3.12/site-packages/urllib3/connection.py", line 236, in connect
    self.sock = self._new_conn()
                ^^^^^^^^^^^^^^^^
  File "/home/gyuri/venv/lib/python3.12/site-packages/urllib3/connection.py", line 211, in _new_conn
    raise NewConnectionError(
urllib3.exceptions.NewConnectionError: <urllib3.connection.HTTPConnection object at 0x725874388470>: Failed to establish a new connection: [Errno 111] Connection refused

The above exception was the direct cause of the following exception:

Traceback (most recent call last):
  File "/home/gyuri/venv/lib/python3.12/site-packages/requests/adapters.py", line 667, in send
    resp = conn.urlopen(
           ^^^^^^^^^^^^^
  File "/home/gyuri/venv/lib/python3.12/site-packages/urllib3/connectionpool.py", line 843, in urlopen
    retries = retries.increment(
              ^^^^^^^^^^^^^^^^^^
  File "/home/gyuri/venv/lib/python3.12/site-packages/urllib3/util/retry.py", line 519, in increment
    raise MaxRetryError(_pool, url, reason) from reason  # type: ignore[arg-type]
    ^^^^^^^^^^^^^^^^^^^^^^^^^^^^^^^^^^^^^^^^^^^^^^^^^^^
urllib3.exceptions.MaxRetryError: HTTPConnectionPool(host='localhost', port=5000): Max retries exceeded with url: /shutdown (Caused by NewConnectionError('<urllib3.connection.HTTPConnection object at 0x725874388470>: Failed to establish a new connection: [Errno 111] Connection refused'))

During handling of the above exception, another exception occurred:

Traceback (most recent call last):
  File "/home/gyuri/Docking/DockerManager/docker_gui.py", line 299, in stop_image_detailer
    requests.post("http://localhost:5000/shutdown")
  File "/home/gyuri/venv/lib/python3.12/site-packages/requests/api.py", line 115, in post
    return request("post", url, data=data, json=json, **kwargs)
           ^^^^^^^^^^^^^^^^^^^^^^^^^^^^^^^^^^^^^^^^^^^^^^^^^^^^
  File "/home/gyuri/venv/lib/python3.12/site-packages/requests/api.py", line 59, in request
    return session.request(method=method, url=url, **kwargs)
           ^^^^^^^^^^^^^^^^^^^^^^^^^^^^^^^^^^^^^^^^^^^^^^^^^
  File "/home/gyuri/venv/lib/python3.12/site-packages/requests/sessions.py", line 589, in request
    resp = self.send(prep, **send_kwargs)
           ^^^^^^^^^^^^^^^^^^^^^^^^^^^^^^
  File "/home/gyuri/venv/lib/python3.12/site-packages/requests/sessions.py", line 703, in send
    r = adapter.send(request, **kwargs)
        ^^^^^^^^^^^^^^^^^^^^^^^^^^^^^^^
  File "/home/gyuri/venv/lib/python3.12/site-packages/requests/adapters.py", line 700, in send
    raise ConnectionError(e, request=request)
requests.exceptions.ConnectionError: HTTPConnectionPool(host='localhost', port=5000): Max retries exceeded with url: /shutdown (Caused by NewConnectionError('<urllib3.connection.HTTPConnection object at 0x725874388470>: Failed to establish a new connection: [Errno 111] Connection refused'))

2024-09-14 13:49:29,780 - logs - INFO - Server thread joined successfully.
2024-09-14 13:54:03,301 - logs - INFO - Server started.
2024-09-14 13:54:06,002 - logs - ERROR - Server is not running or already shut down.
2024-09-14 13:54:06,009 - logs - ERROR - Traceback: Traceback (most recent call last):
  File "/home/gyuri/venv/lib/python3.12/site-packages/urllib3/connection.py", line 196, in _new_conn
    sock = connection.create_connection(
           ^^^^^^^^^^^^^^^^^^^^^^^^^^^^^
  File "/home/gyuri/venv/lib/python3.12/site-packages/urllib3/util/connection.py", line 85, in create_connection
    raise err
  File "/home/gyuri/venv/lib/python3.12/site-packages/urllib3/util/connection.py", line 73, in create_connection
    sock.connect(sa)
ConnectionRefusedError: [Errno 111] Connection refused

The above exception was the direct cause of the following exception:

Traceback (most recent call last):
  File "/home/gyuri/venv/lib/python3.12/site-packages/urllib3/connectionpool.py", line 789, in urlopen
    response = self._make_request(
               ^^^^^^^^^^^^^^^^^^^
  File "/home/gyuri/venv/lib/python3.12/site-packages/urllib3/connectionpool.py", line 495, in _make_request
    conn.request(
  File "/home/gyuri/venv/lib/python3.12/site-packages/urllib3/connection.py", line 398, in request
    self.endheaders()
  File "/usr/lib/python3.12/http/client.py", line 1331, in endheaders
    self._send_output(message_body, encode_chunked=encode_chunked)
  File "/usr/lib/python3.12/http/client.py", line 1091, in _send_output
    self.send(msg)
  File "/usr/lib/python3.12/http/client.py", line 1035, in send
    self.connect()
  File "/home/gyuri/venv/lib/python3.12/site-packages/urllib3/connection.py", line 236, in connect
    self.sock = self._new_conn()
                ^^^^^^^^^^^^^^^^
  File "/home/gyuri/venv/lib/python3.12/site-packages/urllib3/connection.py", line 211, in _new_conn
    raise NewConnectionError(
urllib3.exceptions.NewConnectionError: <urllib3.connection.HTTPConnection object at 0x7efdce284290>: Failed to establish a new connection: [Errno 111] Connection refused

The above exception was the direct cause of the following exception:

Traceback (most recent call last):
  File "/home/gyuri/venv/lib/python3.12/site-packages/requests/adapters.py", line 667, in send
    resp = conn.urlopen(
           ^^^^^^^^^^^^^
  File "/home/gyuri/venv/lib/python3.12/site-packages/urllib3/connectionpool.py", line 843, in urlopen
    retries = retries.increment(
              ^^^^^^^^^^^^^^^^^^
  File "/home/gyuri/venv/lib/python3.12/site-packages/urllib3/util/retry.py", line 519, in increment
    raise MaxRetryError(_pool, url, reason) from reason  # type: ignore[arg-type]
    ^^^^^^^^^^^^^^^^^^^^^^^^^^^^^^^^^^^^^^^^^^^^^^^^^^^
urllib3.exceptions.MaxRetryError: HTTPConnectionPool(host='localhost', port=5000): Max retries exceeded with url: /shutdown (Caused by NewConnectionError('<urllib3.connection.HTTPConnection object at 0x7efdce284290>: Failed to establish a new connection: [Errno 111] Connection refused'))

During handling of the above exception, another exception occurred:

Traceback (most recent call last):
  File "/home/gyuri/Docking/DockerManager/docker_gui.py", line 297, in stop_image_detailer
    requests.post("http://localhost:5000/shutdown")
  File "/home/gyuri/venv/lib/python3.12/site-packages/requests/api.py", line 115, in post
    return request("post", url, data=data, json=json, **kwargs)
           ^^^^^^^^^^^^^^^^^^^^^^^^^^^^^^^^^^^^^^^^^^^^^^^^^^^^
  File "/home/gyuri/venv/lib/python3.12/site-packages/requests/api.py", line 59, in request
    return session.request(method=method, url=url, **kwargs)
           ^^^^^^^^^^^^^^^^^^^^^^^^^^^^^^^^^^^^^^^^^^^^^^^^^
  File "/home/gyuri/venv/lib/python3.12/site-packages/requests/sessions.py", line 589, in request
    resp = self.send(prep, **send_kwargs)
           ^^^^^^^^^^^^^^^^^^^^^^^^^^^^^^
  File "/home/gyuri/venv/lib/python3.12/site-packages/requests/sessions.py", line 703, in send
    r = adapter.send(request, **kwargs)
        ^^^^^^^^^^^^^^^^^^^^^^^^^^^^^^^
  File "/home/gyuri/venv/lib/python3.12/site-packages/requests/adapters.py", line 700, in send
    raise ConnectionError(e, request=request)
requests.exceptions.ConnectionError: HTTPConnectionPool(host='localhost', port=5000): Max retries exceeded with url: /shutdown (Caused by NewConnectionError('<urllib3.connection.HTTPConnection object at 0x7efdce284290>: Failed to establish a new connection: [Errno 111] Connection refused'))

2024-09-14 13:54:06,010 - logs - INFO - Server thread joined successfully.
2024-09-14 13:54:31,189 - logs - INFO - Server started.
2024-09-14 13:54:35,183 - logs - ERROR - Server is not running or already shut down.
2024-09-14 13:54:35,187 - logs - ERROR - Traceback: Traceback (most recent call last):
  File "/home/gyuri/venv/lib/python3.12/site-packages/urllib3/connection.py", line 196, in _new_conn
    sock = connection.create_connection(
           ^^^^^^^^^^^^^^^^^^^^^^^^^^^^^
  File "/home/gyuri/venv/lib/python3.12/site-packages/urllib3/util/connection.py", line 85, in create_connection
    raise err
  File "/home/gyuri/venv/lib/python3.12/site-packages/urllib3/util/connection.py", line 73, in create_connection
    sock.connect(sa)
ConnectionRefusedError: [Errno 111] Connection refused

The above exception was the direct cause of the following exception:

Traceback (most recent call last):
  File "/home/gyuri/venv/lib/python3.12/site-packages/urllib3/connectionpool.py", line 789, in urlopen
    response = self._make_request(
               ^^^^^^^^^^^^^^^^^^^
  File "/home/gyuri/venv/lib/python3.12/site-packages/urllib3/connectionpool.py", line 495, in _make_request
    conn.request(
  File "/home/gyuri/venv/lib/python3.12/site-packages/urllib3/connection.py", line 398, in request
    self.endheaders()
  File "/usr/lib/python3.12/http/client.py", line 1331, in endheaders
    self._send_output(message_body, encode_chunked=encode_chunked)
  File "/usr/lib/python3.12/http/client.py", line 1091, in _send_output
    self.send(msg)
  File "/usr/lib/python3.12/http/client.py", line 1035, in send
    self.connect()
  File "/home/gyuri/venv/lib/python3.12/site-packages/urllib3/connection.py", line 236, in connect
    self.sock = self._new_conn()
                ^^^^^^^^^^^^^^^^
  File "/home/gyuri/venv/lib/python3.12/site-packages/urllib3/connection.py", line 211, in _new_conn
    raise NewConnectionError(
urllib3.exceptions.NewConnectionError: <urllib3.connection.HTTPConnection object at 0x779e83e84620>: Failed to establish a new connection: [Errno 111] Connection refused

The above exception was the direct cause of the following exception:

Traceback (most recent call last):
  File "/home/gyuri/venv/lib/python3.12/site-packages/requests/adapters.py", line 667, in send
    resp = conn.urlopen(
           ^^^^^^^^^^^^^
  File "/home/gyuri/venv/lib/python3.12/site-packages/urllib3/connectionpool.py", line 843, in urlopen
    retries = retries.increment(
              ^^^^^^^^^^^^^^^^^^
  File "/home/gyuri/venv/lib/python3.12/site-packages/urllib3/util/retry.py", line 519, in increment
    raise MaxRetryError(_pool, url, reason) from reason  # type: ignore[arg-type]
    ^^^^^^^^^^^^^^^^^^^^^^^^^^^^^^^^^^^^^^^^^^^^^^^^^^^
urllib3.exceptions.MaxRetryError: HTTPConnectionPool(host='localhost', port=5000): Max retries exceeded with url: /shutdown (Caused by NewConnectionError('<urllib3.connection.HTTPConnection object at 0x779e83e84620>: Failed to establish a new connection: [Errno 111] Connection refused'))

During handling of the above exception, another exception occurred:

Traceback (most recent call last):
  File "/home/gyuri/Docking/DockerManager/docker_gui.py", line 297, in stop_image_detailer
    requests.post("http://localhost:5000/shutdown")
  File "/home/gyuri/venv/lib/python3.12/site-packages/requests/api.py", line 115, in post
    return request("post", url, data=data, json=json, **kwargs)
           ^^^^^^^^^^^^^^^^^^^^^^^^^^^^^^^^^^^^^^^^^^^^^^^^^^^^
  File "/home/gyuri/venv/lib/python3.12/site-packages/requests/api.py", line 59, in request
    return session.request(method=method, url=url, **kwargs)
           ^^^^^^^^^^^^^^^^^^^^^^^^^^^^^^^^^^^^^^^^^^^^^^^^^
  File "/home/gyuri/venv/lib/python3.12/site-packages/requests/sessions.py", line 589, in request
    resp = self.send(prep, **send_kwargs)
           ^^^^^^^^^^^^^^^^^^^^^^^^^^^^^^
  File "/home/gyuri/venv/lib/python3.12/site-packages/requests/sessions.py", line 703, in send
    r = adapter.send(request, **kwargs)
        ^^^^^^^^^^^^^^^^^^^^^^^^^^^^^^^
  File "/home/gyuri/venv/lib/python3.12/site-packages/requests/adapters.py", line 700, in send
    raise ConnectionError(e, request=request)
requests.exceptions.ConnectionError: HTTPConnectionPool(host='localhost', port=5000): Max retries exceeded with url: /shutdown (Caused by NewConnectionError('<urllib3.connection.HTTPConnection object at 0x779e83e84620>: Failed to establish a new connection: [Errno 111] Connection refused'))

2024-09-14 13:54:35,187 - logs - INFO - Server thread joined successfully.
2024-09-14 14:40:19,462 - logs - INFO - Server started.
2024-09-14 14:40:24,428 - logs - ERROR - Server is not running or already shut down.
2024-09-14 14:40:24,431 - logs - ERROR - Traceback: Traceback (most recent call last):
  File "/home/gyuri/venv/lib/python3.12/site-packages/urllib3/connection.py", line 196, in _new_conn
    sock = connection.create_connection(
           ^^^^^^^^^^^^^^^^^^^^^^^^^^^^^
  File "/home/gyuri/venv/lib/python3.12/site-packages/urllib3/util/connection.py", line 85, in create_connection
    raise err
  File "/home/gyuri/venv/lib/python3.12/site-packages/urllib3/util/connection.py", line 73, in create_connection
    sock.connect(sa)
ConnectionRefusedError: [Errno 111] Connection refused

The above exception was the direct cause of the following exception:

Traceback (most recent call last):
  File "/home/gyuri/venv/lib/python3.12/site-packages/urllib3/connectionpool.py", line 789, in urlopen
    response = self._make_request(
               ^^^^^^^^^^^^^^^^^^^
  File "/home/gyuri/venv/lib/python3.12/site-packages/urllib3/connectionpool.py", line 495, in _make_request
    conn.request(
  File "/home/gyuri/venv/lib/python3.12/site-packages/urllib3/connection.py", line 398, in request
    self.endheaders()
  File "/usr/lib/python3.12/http/client.py", line 1331, in endheaders
    self._send_output(message_body, encode_chunked=encode_chunked)
  File "/usr/lib/python3.12/http/client.py", line 1091, in _send_output
    self.send(msg)
  File "/usr/lib/python3.12/http/client.py", line 1035, in send
    self.connect()
  File "/home/gyuri/venv/lib/python3.12/site-packages/urllib3/connection.py", line 236, in connect
    self.sock = self._new_conn()
                ^^^^^^^^^^^^^^^^
  File "/home/gyuri/venv/lib/python3.12/site-packages/urllib3/connection.py", line 211, in _new_conn
    raise NewConnectionError(
urllib3.exceptions.NewConnectionError: <urllib3.connection.HTTPConnection object at 0x78255fd882f0>: Failed to establish a new connection: [Errno 111] Connection refused

The above exception was the direct cause of the following exception:

Traceback (most recent call last):
  File "/home/gyuri/venv/lib/python3.12/site-packages/requests/adapters.py", line 667, in send
    resp = conn.urlopen(
           ^^^^^^^^^^^^^
  File "/home/gyuri/venv/lib/python3.12/site-packages/urllib3/connectionpool.py", line 843, in urlopen
    retries = retries.increment(
              ^^^^^^^^^^^^^^^^^^
  File "/home/gyuri/venv/lib/python3.12/site-packages/urllib3/util/retry.py", line 519, in increment
    raise MaxRetryError(_pool, url, reason) from reason  # type: ignore[arg-type]
    ^^^^^^^^^^^^^^^^^^^^^^^^^^^^^^^^^^^^^^^^^^^^^^^^^^^
urllib3.exceptions.MaxRetryError: HTTPConnectionPool(host='localhost', port=5000): Max retries exceeded with url: /shutdown (Caused by NewConnectionError('<urllib3.connection.HTTPConnection object at 0x78255fd882f0>: Failed to establish a new connection: [Errno 111] Connection refused'))

During handling of the above exception, another exception occurred:

Traceback (most recent call last):
  File "/home/gyuri/Docking/DockerManager/docker_gui.py", line 297, in stop_image_detailer
    requests.post("http://localhost:5000/shutdown")
  File "/home/gyuri/venv/lib/python3.12/site-packages/requests/api.py", line 115, in post
    return request("post", url, data=data, json=json, **kwargs)
           ^^^^^^^^^^^^^^^^^^^^^^^^^^^^^^^^^^^^^^^^^^^^^^^^^^^^
  File "/home/gyuri/venv/lib/python3.12/site-packages/requests/api.py", line 59, in request
    return session.request(method=method, url=url, **kwargs)
           ^^^^^^^^^^^^^^^^^^^^^^^^^^^^^^^^^^^^^^^^^^^^^^^^^
  File "/home/gyuri/venv/lib/python3.12/site-packages/requests/sessions.py", line 589, in request
    resp = self.send(prep, **send_kwargs)
           ^^^^^^^^^^^^^^^^^^^^^^^^^^^^^^
  File "/home/gyuri/venv/lib/python3.12/site-packages/requests/sessions.py", line 703, in send
    r = adapter.send(request, **kwargs)
        ^^^^^^^^^^^^^^^^^^^^^^^^^^^^^^^
  File "/home/gyuri/venv/lib/python3.12/site-packages/requests/adapters.py", line 700, in send
    raise ConnectionError(e, request=request)
requests.exceptions.ConnectionError: HTTPConnectionPool(host='localhost', port=5000): Max retries exceeded with url: /shutdown (Caused by NewConnectionError('<urllib3.connection.HTTPConnection object at 0x78255fd882f0>: Failed to establish a new connection: [Errno 111] Connection refused'))

2024-09-14 14:40:24,431 - logs - INFO - Server thread joined successfully.
2024-09-14 14:46:05,657 - logs - INFO - Server started.
2024-09-14 14:46:05,661 - werkzeug - INFO - [31m[1mWARNING: This is a development server. Do not use it in a production deployment. Use a production WSGI server instead.[0m
 * Running on http://127.0.0.1:5000
2024-09-14 14:46:05,662 - werkzeug - INFO - [33mPress CTRL+C to quit[0m
2024-09-14 14:46:10,355 - werkzeug - INFO - 127.0.0.1 - - [14/Sep/2024 14:46:10] "GET / HTTP/1.1" 200 -
2024-09-14 14:46:10,393 - werkzeug - INFO - 127.0.0.1 - - [14/Sep/2024 14:46:10] "[36mGET /static/styles.css HTTP/1.1[0m" 304 -
2024-09-14 14:46:12,358 - werkzeug - INFO - 127.0.0.1 - - [14/Sep/2024 14:46:12] "GET /layer_comparison HTTP/1.1" 200 -
2024-09-14 14:46:12,377 - werkzeug - INFO - 127.0.0.1 - - [14/Sep/2024 14:46:12] "[36mGET /static/styles.css HTTP/1.1[0m" 304 -
2024-09-14 14:46:14,267 - werkzeug - INFO - 127.0.0.1 - - [14/Sep/2024 14:46:14] "GET /images HTTP/1.1" 200 -
2024-09-14 14:46:14,289 - werkzeug - INFO - 127.0.0.1 - - [14/Sep/2024 14:46:14] "[36mGET /static/styles.css HTTP/1.1[0m" 304 -
2024-09-14 14:46:15,130 - Image_detailer.app - ERROR - Exception on /image [POST]
Traceback (most recent call last):
  File "/home/gyuri/venv/lib/python3.12/site-packages/flask/app.py", line 1473, in wsgi_app
    response = self.full_dispatch_request()
               ^^^^^^^^^^^^^^^^^^^^^^^^^^^^
  File "/home/gyuri/venv/lib/python3.12/site-packages/flask/app.py", line 882, in full_dispatch_request
    rv = self.handle_user_exception(e)
         ^^^^^^^^^^^^^^^^^^^^^^^^^^^^^
  File "/home/gyuri/venv/lib/python3.12/site-packages/flask/app.py", line 880, in full_dispatch_request
    rv = self.dispatch_request()
         ^^^^^^^^^^^^^^^^^^^^^^^
  File "/home/gyuri/venv/lib/python3.12/site-packages/flask/app.py", line 865, in dispatch_request
    return self.ensure_sync(self.view_functions[rule.endpoint])(**view_args)  # type: ignore[no-any-return]
           ^^^^^^^^^^^^^^^^^^^^^^^^^^^^^^^^^^^^^^^^^^^^^^^^^^^^^^^^^^^^^^^^^
  File "/home/gyuri/Docking/DockerManager/Image_detailer/app.py", line 136, in image
    layers = get_image_history(image_name)
             ^^^^^^^^^^^^^^^^^
NameError: name 'get_image_history' is not defined
2024-09-14 14:46:15,169 - werkzeug - INFO - 127.0.0.1 - - [14/Sep/2024 14:46:15] "[35m[1mPOST /image HTTP/1.1[0m" 500 -
2024-09-14 14:46:25,129 - Image_detailer.app - ERROR - Exception on /image [POST]
Traceback (most recent call last):
  File "/home/gyuri/venv/lib/python3.12/site-packages/flask/app.py", line 1473, in wsgi_app
    response = self.full_dispatch_request()
               ^^^^^^^^^^^^^^^^^^^^^^^^^^^^
  File "/home/gyuri/venv/lib/python3.12/site-packages/flask/app.py", line 882, in full_dispatch_request
    rv = self.handle_user_exception(e)
         ^^^^^^^^^^^^^^^^^^^^^^^^^^^^^
  File "/home/gyuri/venv/lib/python3.12/site-packages/flask/app.py", line 880, in full_dispatch_request
    rv = self.dispatch_request()
         ^^^^^^^^^^^^^^^^^^^^^^^
  File "/home/gyuri/venv/lib/python3.12/site-packages/flask/app.py", line 865, in dispatch_request
    return self.ensure_sync(self.view_functions[rule.endpoint])(**view_args)  # type: ignore[no-any-return]
           ^^^^^^^^^^^^^^^^^^^^^^^^^^^^^^^^^^^^^^^^^^^^^^^^^^^^^^^^^^^^^^^^^
  File "/home/gyuri/Docking/DockerManager/Image_detailer/app.py", line 136, in image
    layers = get_image_history(image_name)
             ^^^^^^^^^^^^^^^^^
NameError: name 'get_image_history' is not defined
2024-09-14 14:46:25,140 - werkzeug - INFO - 127.0.0.1 - - [14/Sep/2024 14:46:25] "[35m[1mPOST /image HTTP/1.1[0m" 500 -
2024-09-14 14:46:26,771 - Image_detailer.app - ERROR - Exception on /vulnerabilities [GET]
Traceback (most recent call last):
  File "/home/gyuri/venv/lib/python3.12/site-packages/flask/app.py", line 1473, in wsgi_app
    response = self.full_dispatch_request()
               ^^^^^^^^^^^^^^^^^^^^^^^^^^^^
  File "/home/gyuri/venv/lib/python3.12/site-packages/flask/app.py", line 882, in full_dispatch_request
    rv = self.handle_user_exception(e)
         ^^^^^^^^^^^^^^^^^^^^^^^^^^^^^
  File "/home/gyuri/venv/lib/python3.12/site-packages/flask/app.py", line 880, in full_dispatch_request
    rv = self.dispatch_request()
         ^^^^^^^^^^^^^^^^^^^^^^^
  File "/home/gyuri/venv/lib/python3.12/site-packages/flask/app.py", line 865, in dispatch_request
    return self.ensure_sync(self.view_functions[rule.endpoint])(**view_args)  # type: ignore[no-any-return]
           ^^^^^^^^^^^^^^^^^^^^^^^^^^^^^^^^^^^^^^^^^^^^^^^^^^^^^^^^^^^^^^^^^
  File "/home/gyuri/Docking/DockerManager/Image_detailer/app.py", line 547, in vulnerabilities
    available_images = get_docker_images()  # Get the list of available Docker images
                       ^^^^^^^^^^^^^^^^^
NameError: name 'get_docker_images' is not defined
2024-09-14 14:46:26,779 - werkzeug - INFO - 127.0.0.1 - - [14/Sep/2024 14:46:26] "[35m[1mGET /vulnerabilities HTTP/1.1[0m" 500 -
2024-09-14 14:46:29,508 - werkzeug - INFO - 127.0.0.1 - - [14/Sep/2024 14:46:29] "GET /images HTTP/1.1" 200 -
2024-09-14 14:46:29,526 - werkzeug - INFO - 127.0.0.1 - - [14/Sep/2024 14:46:29] "[36mGET /static/styles.css HTTP/1.1[0m" 304 -
2024-09-14 14:46:30,154 - werkzeug - INFO - 127.0.0.1 - - [14/Sep/2024 14:46:30] "GET /images HTTP/1.1" 200 -
2024-09-14 14:46:30,175 - werkzeug - INFO - 127.0.0.1 - - [14/Sep/2024 14:46:30] "[36mGET /static/styles.css HTTP/1.1[0m" 304 -
2024-09-14 14:46:30,481 - werkzeug - INFO - 127.0.0.1 - - [14/Sep/2024 14:46:30] "GET /images HTTP/1.1" 200 -
2024-09-14 14:46:30,499 - werkzeug - INFO - 127.0.0.1 - - [14/Sep/2024 14:46:30] "[36mGET /static/styles.css HTTP/1.1[0m" 304 -
2024-09-14 14:46:30,716 - werkzeug - INFO - 127.0.0.1 - - [14/Sep/2024 14:46:30] "GET /images HTTP/1.1" 200 -
2024-09-14 14:46:30,735 - werkzeug - INFO - 127.0.0.1 - - [14/Sep/2024 14:46:30] "[36mGET /static/styles.css HTTP/1.1[0m" 304 -
2024-09-14 14:46:32,218 - Image_detailer.app - ERROR - Exception on /vulnerabilities [GET]
Traceback (most recent call last):
  File "/home/gyuri/venv/lib/python3.12/site-packages/flask/app.py", line 1473, in wsgi_app
    response = self.full_dispatch_request()
               ^^^^^^^^^^^^^^^^^^^^^^^^^^^^
  File "/home/gyuri/venv/lib/python3.12/site-packages/flask/app.py", line 882, in full_dispatch_request
    rv = self.handle_user_exception(e)
         ^^^^^^^^^^^^^^^^^^^^^^^^^^^^^
  File "/home/gyuri/venv/lib/python3.12/site-packages/flask/app.py", line 880, in full_dispatch_request
    rv = self.dispatch_request()
         ^^^^^^^^^^^^^^^^^^^^^^^
  File "/home/gyuri/venv/lib/python3.12/site-packages/flask/app.py", line 865, in dispatch_request
    return self.ensure_sync(self.view_functions[rule.endpoint])(**view_args)  # type: ignore[no-any-return]
           ^^^^^^^^^^^^^^^^^^^^^^^^^^^^^^^^^^^^^^^^^^^^^^^^^^^^^^^^^^^^^^^^^
  File "/home/gyuri/Docking/DockerManager/Image_detailer/app.py", line 547, in vulnerabilities
    available_images = get_docker_images()  # Get the list of available Docker images
                       ^^^^^^^^^^^^^^^^^
NameError: name 'get_docker_images' is not defined
2024-09-14 14:46:32,226 - werkzeug - INFO - 127.0.0.1 - - [14/Sep/2024 14:46:32] "[35m[1mGET /vulnerabilities HTTP/1.1[0m" 500 -
2024-09-14 14:46:33,941 - werkzeug - INFO - 127.0.0.1 - - [14/Sep/2024 14:46:33] "GET /image_metadata HTTP/1.1" 200 -
2024-09-14 14:46:33,963 - werkzeug - INFO - 127.0.0.1 - - [14/Sep/2024 14:46:33] "[36mGET /static/styles.css HTTP/1.1[0m" 304 -
2024-09-14 14:46:34,883 - werkzeug - INFO - 127.0.0.1 - - [14/Sep/2024 14:46:34] "GET /logs_build_info HTTP/1.1" 200 -
2024-09-14 14:46:34,903 - werkzeug - INFO - 127.0.0.1 - - [14/Sep/2024 14:46:34] "[36mGET /static/styles.css HTTP/1.1[0m" 304 -
2024-09-14 14:46:35,473 - werkzeug - INFO - 127.0.0.1 - - [14/Sep/2024 14:46:35] "GET /interactive_visualizations HTTP/1.1" 200 -
2024-09-14 14:46:35,496 - werkzeug - INFO - 127.0.0.1 - - [14/Sep/2024 14:46:35] "[36mGET /static/styles.css HTTP/1.1[0m" 304 -
2024-09-14 14:46:37,780 - werkzeug - INFO - 127.0.0.1 - - [14/Sep/2024 14:46:37] "[35m[1mPOST /interactive_visualizations HTTP/1.1[0m" 500 -
2024-09-14 14:46:45,340 - Image_detailer.app - ERROR - Exception on /shutdown [POST]
Traceback (most recent call last):
  File "/home/gyuri/venv/lib/python3.12/site-packages/flask/app.py", line 1473, in wsgi_app
    response = self.full_dispatch_request()
               ^^^^^^^^^^^^^^^^^^^^^^^^^^^^
  File "/home/gyuri/venv/lib/python3.12/site-packages/flask/app.py", line 882, in full_dispatch_request
    rv = self.handle_user_exception(e)
         ^^^^^^^^^^^^^^^^^^^^^^^^^^^^^
  File "/home/gyuri/venv/lib/python3.12/site-packages/flask/app.py", line 880, in full_dispatch_request
    rv = self.dispatch_request()
         ^^^^^^^^^^^^^^^^^^^^^^^
  File "/home/gyuri/venv/lib/python3.12/site-packages/flask/app.py", line 865, in dispatch_request
    return self.ensure_sync(self.view_functions[rule.endpoint])(**view_args)  # type: ignore[no-any-return]
           ^^^^^^^^^^^^^^^^^^^^^^^^^^^^^^^^^^^^^^^^^^^^^^^^^^^^^^^^^^^^^^^^^
  File "/home/gyuri/Docking/DockerManager/Image_detailer/app.py", line 120, in shutdown
    raise RuntimeError('Not running with the Werkzeug Server')
RuntimeError: Not running with the Werkzeug Server
2024-09-14 14:46:45,341 - werkzeug - INFO - 127.0.0.1 - - [14/Sep/2024 14:46:45] "[35m[1mPOST /shutdown HTTP/1.1[0m" 500 -
2024-09-14 14:46:45,341 - logs - INFO - Server shutdown request sent.
2024-09-14 14:46:45,341 - logs - INFO - Server thread joined successfully.
2024-09-14 14:47:34,963 - logs - INFO - Server started.
2024-09-14 14:47:34,968 - werkzeug - INFO - [31m[1mWARNING: This is a development server. Do not use it in a production deployment. Use a production WSGI server instead.[0m
 * Running on http://127.0.0.1:5000
2024-09-14 14:47:34,968 - werkzeug - INFO - [33mPress CTRL+C to quit[0m
2024-09-14 14:47:38,887 - werkzeug - INFO - 127.0.0.1 - - [14/Sep/2024 14:47:38] "[35m[1mPOST /interactive_visualizations HTTP/1.1[0m" 500 -
2024-09-14 14:47:41,532 - werkzeug - INFO - 127.0.0.1 - - [14/Sep/2024 14:47:41] "GET / HTTP/1.1" 200 -
2024-09-14 14:47:41,561 - werkzeug - INFO - 127.0.0.1 - - [14/Sep/2024 14:47:41] "[36mGET /static/styles.css HTTP/1.1[0m" 304 -
2024-09-14 14:47:43,236 - Image_detailer.app - ERROR - Exception on /vulnerabilities [GET]
Traceback (most recent call last):
  File "/home/gyuri/venv/lib/python3.12/site-packages/flask/app.py", line 1473, in wsgi_app
    response = self.full_dispatch_request()
               ^^^^^^^^^^^^^^^^^^^^^^^^^^^^
  File "/home/gyuri/venv/lib/python3.12/site-packages/flask/app.py", line 882, in full_dispatch_request
    rv = self.handle_user_exception(e)
         ^^^^^^^^^^^^^^^^^^^^^^^^^^^^^
  File "/home/gyuri/venv/lib/python3.12/site-packages/flask/app.py", line 880, in full_dispatch_request
    rv = self.dispatch_request()
         ^^^^^^^^^^^^^^^^^^^^^^^
  File "/home/gyuri/venv/lib/python3.12/site-packages/flask/app.py", line 865, in dispatch_request
    return self.ensure_sync(self.view_functions[rule.endpoint])(**view_args)  # type: ignore[no-any-return]
           ^^^^^^^^^^^^^^^^^^^^^^^^^^^^^^^^^^^^^^^^^^^^^^^^^^^^^^^^^^^^^^^^^
  File "/home/gyuri/Docking/DockerManager/Image_detailer/app.py", line 574, in vulnerabilities
    available_images = get_docker_images()  # Get the list of available Docker images
                       ^^^^^^^^^^^^^^^^^
NameError: name 'get_docker_images' is not defined
2024-09-14 14:47:43,247 - werkzeug - INFO - 127.0.0.1 - - [14/Sep/2024 14:47:43] "[35m[1mGET /vulnerabilities HTTP/1.1[0m" 500 -
2024-09-14 14:47:53,772 - werkzeug - INFO - 127.0.0.1 - - [14/Sep/2024 14:47:53] "GET /volume_network_info HTTP/1.1" 200 -
2024-09-14 14:47:53,790 - werkzeug - INFO - 127.0.0.1 - - [14/Sep/2024 14:47:53] "[36mGET /static/styles.css HTTP/1.1[0m" 304 -
2024-09-14 14:48:08,139 - Image_detailer.app - ERROR - Exception on /vulnerabilities [GET]
Traceback (most recent call last):
  File "/home/gyuri/venv/lib/python3.12/site-packages/flask/app.py", line 1473, in wsgi_app
    response = self.full_dispatch_request()
               ^^^^^^^^^^^^^^^^^^^^^^^^^^^^
  File "/home/gyuri/venv/lib/python3.12/site-packages/flask/app.py", line 882, in full_dispatch_request
    rv = self.handle_user_exception(e)
         ^^^^^^^^^^^^^^^^^^^^^^^^^^^^^
  File "/home/gyuri/venv/lib/python3.12/site-packages/flask/app.py", line 880, in full_dispatch_request
    rv = self.dispatch_request()
         ^^^^^^^^^^^^^^^^^^^^^^^
  File "/home/gyuri/venv/lib/python3.12/site-packages/flask/app.py", line 865, in dispatch_request
    return self.ensure_sync(self.view_functions[rule.endpoint])(**view_args)  # type: ignore[no-any-return]
           ^^^^^^^^^^^^^^^^^^^^^^^^^^^^^^^^^^^^^^^^^^^^^^^^^^^^^^^^^^^^^^^^^
  File "/home/gyuri/Docking/DockerManager/Image_detailer/app.py", line 574, in vulnerabilities
    available_images = get_docker_images()  # Get the list of available Docker images
                       ^^^^^^^^^^^^^^^^^
NameError: name 'get_docker_images' is not defined
2024-09-14 14:48:08,146 - werkzeug - INFO - 127.0.0.1 - - [14/Sep/2024 14:48:08] "[35m[1mGET /vulnerabilities HTTP/1.1[0m" 500 -
2024-09-14 14:48:29,945 - Image_detailer.app - ERROR - Exception on /vulnerabilities [GET]
Traceback (most recent call last):
  File "/home/gyuri/venv/lib/python3.12/site-packages/flask/app.py", line 1473, in wsgi_app
    response = self.full_dispatch_request()
               ^^^^^^^^^^^^^^^^^^^^^^^^^^^^
  File "/home/gyuri/venv/lib/python3.12/site-packages/flask/app.py", line 882, in full_dispatch_request
    rv = self.handle_user_exception(e)
         ^^^^^^^^^^^^^^^^^^^^^^^^^^^^^
  File "/home/gyuri/venv/lib/python3.12/site-packages/flask/app.py", line 880, in full_dispatch_request
    rv = self.dispatch_request()
         ^^^^^^^^^^^^^^^^^^^^^^^
  File "/home/gyuri/venv/lib/python3.12/site-packages/flask/app.py", line 865, in dispatch_request
    return self.ensure_sync(self.view_functions[rule.endpoint])(**view_args)  # type: ignore[no-any-return]
           ^^^^^^^^^^^^^^^^^^^^^^^^^^^^^^^^^^^^^^^^^^^^^^^^^^^^^^^^^^^^^^^^^
  File "/home/gyuri/Docking/DockerManager/Image_detailer/app.py", line 574, in vulnerabilities
    image_name = request.form.get('image_name')
                   ^^^^^^^^^^^^^^^^^
NameError: name 'get_docker_images' is not defined
2024-09-14 14:48:29,954 - werkzeug - INFO - 127.0.0.1 - - [14/Sep/2024 14:48:29] "[35m[1mGET /vulnerabilities HTTP/1.1[0m" 500 -
2024-09-14 14:48:30,449 - Image_detailer.app - ERROR - Exception on /vulnerabilities [GET]
Traceback (most recent call last):
  File "/home/gyuri/venv/lib/python3.12/site-packages/flask/app.py", line 1473, in wsgi_app
    response = self.full_dispatch_request()
               ^^^^^^^^^^^^^^^^^^^^^^^^^^^^
  File "/home/gyuri/venv/lib/python3.12/site-packages/flask/app.py", line 882, in full_dispatch_request
    rv = self.handle_user_exception(e)
         ^^^^^^^^^^^^^^^^^^^^^^^^^^^^^
  File "/home/gyuri/venv/lib/python3.12/site-packages/flask/app.py", line 880, in full_dispatch_request
    rv = self.dispatch_request()
         ^^^^^^^^^^^^^^^^^^^^^^^
  File "/home/gyuri/venv/lib/python3.12/site-packages/flask/app.py", line 865, in dispatch_request
    return self.ensure_sync(self.view_functions[rule.endpoint])(**view_args)  # type: ignore[no-any-return]
           ^^^^^^^^^^^^^^^^^^^^^^^^^^^^^^^^^^^^^^^^^^^^^^^^^^^^^^^^^^^^^^^^^
  File "/home/gyuri/Docking/DockerManager/Image_detailer/app.py", line 574, in vulnerabilities
    image_name = request.form.get('image_name')
                   ^^^^^^^^^^^^^^^^^
NameError: name 'get_docker_images' is not defined
2024-09-14 14:48:30,456 - werkzeug - INFO - 127.0.0.1 - - [14/Sep/2024 14:48:30] "[35m[1mGET /vulnerabilities HTTP/1.1[0m" 500 -
2024-09-14 14:48:54,734 - Image_detailer.app - ERROR - Exception on /shutdown [POST]
Traceback (most recent call last):
  File "/home/gyuri/venv/lib/python3.12/site-packages/flask/app.py", line 1473, in wsgi_app
    response = self.full_dispatch_request()
               ^^^^^^^^^^^^^^^^^^^^^^^^^^^^
  File "/home/gyuri/venv/lib/python3.12/site-packages/flask/app.py", line 882, in full_dispatch_request
    rv = self.handle_user_exception(e)
         ^^^^^^^^^^^^^^^^^^^^^^^^^^^^^
  File "/home/gyuri/venv/lib/python3.12/site-packages/flask/app.py", line 880, in full_dispatch_request
    rv = self.dispatch_request()
         ^^^^^^^^^^^^^^^^^^^^^^^
  File "/home/gyuri/venv/lib/python3.12/site-packages/flask/app.py", line 865, in dispatch_request
    return self.ensure_sync(self.view_functions[rule.endpoint])(**view_args)  # type: ignore[no-any-return]
           ^^^^^^^^^^^^^^^^^^^^^^^^^^^^^^^^^^^^^^^^^^^^^^^^^^^^^^^^^^^^^^^^^
  File "/home/gyuri/Docking/DockerManager/Image_detailer/app.py", line 147, in shutdown
    raise RuntimeError('Not running with the Werkzeug Server')
RuntimeError: Not running with the Werkzeug Server
2024-09-14 14:48:54,735 - werkzeug - INFO - 127.0.0.1 - - [14/Sep/2024 14:48:54] "[35m[1mPOST /shutdown HTTP/1.1[0m" 500 -
2024-09-14 14:48:54,736 - logs - INFO - Server shutdown request sent.
2024-09-14 14:48:54,736 - logs - INFO - Server thread joined successfully.
2024-09-14 14:53:30,929 - logs - INFO - Server started.
2024-09-14 14:53:30,934 - werkzeug - INFO - [31m[1mWARNING: This is a development server. Do not use it in a production deployment. Use a production WSGI server instead.[0m
 * Running on http://127.0.0.1:5000
2024-09-14 14:53:30,934 - werkzeug - INFO - [33mPress CTRL+C to quit[0m
2024-09-14 14:53:33,695 - Image_detailer.app - ERROR - Exception on /vulnerabilities [GET]
Traceback (most recent call last):
  File "/home/gyuri/venv/lib/python3.12/site-packages/flask/app.py", line 1473, in wsgi_app
    response = self.full_dispatch_request()
               ^^^^^^^^^^^^^^^^^^^^^^^^^^^^
  File "/home/gyuri/venv/lib/python3.12/site-packages/flask/app.py", line 882, in full_dispatch_request
    rv = self.handle_user_exception(e)
         ^^^^^^^^^^^^^^^^^^^^^^^^^^^^^
  File "/home/gyuri/venv/lib/python3.12/site-packages/flask/app.py", line 880, in full_dispatch_request
    rv = self.dispatch_request()
         ^^^^^^^^^^^^^^^^^^^^^^^
  File "/home/gyuri/venv/lib/python3.12/site-packages/flask/app.py", line 865, in dispatch_request
    return self.ensure_sync(self.view_functions[rule.endpoint])(**view_args)  # type: ignore[no-any-return]
           ^^^^^^^^^^^^^^^^^^^^^^^^^^^^^^^^^^^^^^^^^^^^^^^^^^^^^^^^^^^^^^^^^
TypeError: ImageD.vulnerabilities() missing 1 required positional argument: 'self'
2024-09-14 14:53:33,697 - werkzeug - INFO - 127.0.0.1 - - [14/Sep/2024 14:53:33] "[35m[1mGET /vulnerabilities HTTP/1.1[0m" 500 -
2024-09-14 14:53:39,369 - Image_detailer.app - ERROR - Exception on / [GET]
Traceback (most recent call last):
  File "/home/gyuri/venv/lib/python3.12/site-packages/flask/app.py", line 1473, in wsgi_app
    response = self.full_dispatch_request()
               ^^^^^^^^^^^^^^^^^^^^^^^^^^^^
  File "/home/gyuri/venv/lib/python3.12/site-packages/flask/app.py", line 882, in full_dispatch_request
    rv = self.handle_user_exception(e)
         ^^^^^^^^^^^^^^^^^^^^^^^^^^^^^
  File "/home/gyuri/venv/lib/python3.12/site-packages/flask/app.py", line 880, in full_dispatch_request
    rv = self.dispatch_request()
         ^^^^^^^^^^^^^^^^^^^^^^^
  File "/home/gyuri/venv/lib/python3.12/site-packages/flask/app.py", line 865, in dispatch_request
    return self.ensure_sync(self.view_functions[rule.endpoint])(**view_args)  # type: ignore[no-any-return]
           ^^^^^^^^^^^^^^^^^^^^^^^^^^^^^^^^^^^^^^^^^^^^^^^^^^^^^^^^^^^^^^^^^
TypeError: ImageD.index() missing 1 required positional argument: 'self'
2024-09-14 14:53:39,370 - werkzeug - INFO - 127.0.0.1 - - [14/Sep/2024 14:53:39] "[35m[1mGET / HTTP/1.1[0m" 500 -
2024-09-14 14:53:42,251 - Image_detailer.app - ERROR - Exception on / [GET]
Traceback (most recent call last):
  File "/home/gyuri/venv/lib/python3.12/site-packages/flask/app.py", line 1473, in wsgi_app
    response = self.full_dispatch_request()
               ^^^^^^^^^^^^^^^^^^^^^^^^^^^^
  File "/home/gyuri/venv/lib/python3.12/site-packages/flask/app.py", line 882, in full_dispatch_request
    rv = self.handle_user_exception(e)
         ^^^^^^^^^^^^^^^^^^^^^^^^^^^^^
  File "/home/gyuri/venv/lib/python3.12/site-packages/flask/app.py", line 880, in full_dispatch_request
    rv = self.dispatch_request()
         ^^^^^^^^^^^^^^^^^^^^^^^
  File "/home/gyuri/venv/lib/python3.12/site-packages/flask/app.py", line 865, in dispatch_request
    return self.ensure_sync(self.view_functions[rule.endpoint])(**view_args)  # type: ignore[no-any-return]
           ^^^^^^^^^^^^^^^^^^^^^^^^^^^^^^^^^^^^^^^^^^^^^^^^^^^^^^^^^^^^^^^^^
TypeError: ImageD.index() missing 1 required positional argument: 'self'
2024-09-14 14:53:42,252 - werkzeug - INFO - 127.0.0.1 - - [14/Sep/2024 14:53:42] "[35m[1mGET / HTTP/1.1[0m" 500 -
2024-09-14 14:53:42,735 - Image_detailer.app - ERROR - Exception on / [GET]
Traceback (most recent call last):
  File "/home/gyuri/venv/lib/python3.12/site-packages/flask/app.py", line 1473, in wsgi_app
    response = self.full_dispatch_request()
               ^^^^^^^^^^^^^^^^^^^^^^^^^^^^
  File "/home/gyuri/venv/lib/python3.12/site-packages/flask/app.py", line 882, in full_dispatch_request
    rv = self.handle_user_exception(e)
         ^^^^^^^^^^^^^^^^^^^^^^^^^^^^^
  File "/home/gyuri/venv/lib/python3.12/site-packages/flask/app.py", line 880, in full_dispatch_request
    rv = self.dispatch_request()
         ^^^^^^^^^^^^^^^^^^^^^^^
  File "/home/gyuri/venv/lib/python3.12/site-packages/flask/app.py", line 865, in dispatch_request
    return self.ensure_sync(self.view_functions[rule.endpoint])(**view_args)  # type: ignore[no-any-return]
           ^^^^^^^^^^^^^^^^^^^^^^^^^^^^^^^^^^^^^^^^^^^^^^^^^^^^^^^^^^^^^^^^^
TypeError: ImageD.index() missing 1 required positional argument: 'self'
2024-09-14 14:53:42,736 - werkzeug - INFO - 127.0.0.1 - - [14/Sep/2024 14:53:42] "[35m[1mGET / HTTP/1.1[0m" 500 -
2024-09-14 14:53:42,927 - Image_detailer.app - ERROR - Exception on / [GET]
Traceback (most recent call last):
  File "/home/gyuri/venv/lib/python3.12/site-packages/flask/app.py", line 1473, in wsgi_app
    response = self.full_dispatch_request()
               ^^^^^^^^^^^^^^^^^^^^^^^^^^^^
  File "/home/gyuri/venv/lib/python3.12/site-packages/flask/app.py", line 882, in full_dispatch_request
    rv = self.handle_user_exception(e)
         ^^^^^^^^^^^^^^^^^^^^^^^^^^^^^
  File "/home/gyuri/venv/lib/python3.12/site-packages/flask/app.py", line 880, in full_dispatch_request
    rv = self.dispatch_request()
         ^^^^^^^^^^^^^^^^^^^^^^^
  File "/home/gyuri/venv/lib/python3.12/site-packages/flask/app.py", line 865, in dispatch_request
    return self.ensure_sync(self.view_functions[rule.endpoint])(**view_args)  # type: ignore[no-any-return]
           ^^^^^^^^^^^^^^^^^^^^^^^^^^^^^^^^^^^^^^^^^^^^^^^^^^^^^^^^^^^^^^^^^
TypeError: ImageD.index() missing 1 required positional argument: 'self'
2024-09-14 14:53:42,928 - werkzeug - INFO - 127.0.0.1 - - [14/Sep/2024 14:53:42] "[35m[1mGET / HTTP/1.1[0m" 500 -
2024-09-14 14:53:43,102 - Image_detailer.app - ERROR - Exception on / [GET]
Traceback (most recent call last):
  File "/home/gyuri/venv/lib/python3.12/site-packages/flask/app.py", line 1473, in wsgi_app
    response = self.full_dispatch_request()
               ^^^^^^^^^^^^^^^^^^^^^^^^^^^^
  File "/home/gyuri/venv/lib/python3.12/site-packages/flask/app.py", line 882, in full_dispatch_request
    rv = self.handle_user_exception(e)
         ^^^^^^^^^^^^^^^^^^^^^^^^^^^^^
  File "/home/gyuri/venv/lib/python3.12/site-packages/flask/app.py", line 880, in full_dispatch_request
    rv = self.dispatch_request()
         ^^^^^^^^^^^^^^^^^^^^^^^
  File "/home/gyuri/venv/lib/python3.12/site-packages/flask/app.py", line 865, in dispatch_request
    return self.ensure_sync(self.view_functions[rule.endpoint])(**view_args)  # type: ignore[no-any-return]
           ^^^^^^^^^^^^^^^^^^^^^^^^^^^^^^^^^^^^^^^^^^^^^^^^^^^^^^^^^^^^^^^^^
TypeError: ImageD.index() missing 1 required positional argument: 'self'
2024-09-14 14:53:43,103 - werkzeug - INFO - 127.0.0.1 - - [14/Sep/2024 14:53:43] "[35m[1mGET / HTTP/1.1[0m" 500 -
2024-09-14 14:53:43,281 - Image_detailer.app - ERROR - Exception on / [GET]
Traceback (most recent call last):
  File "/home/gyuri/venv/lib/python3.12/site-packages/flask/app.py", line 1473, in wsgi_app
    response = self.full_dispatch_request()
               ^^^^^^^^^^^^^^^^^^^^^^^^^^^^
  File "/home/gyuri/venv/lib/python3.12/site-packages/flask/app.py", line 882, in full_dispatch_request
    rv = self.handle_user_exception(e)
         ^^^^^^^^^^^^^^^^^^^^^^^^^^^^^
  File "/home/gyuri/venv/lib/python3.12/site-packages/flask/app.py", line 880, in full_dispatch_request
    rv = self.dispatch_request()
         ^^^^^^^^^^^^^^^^^^^^^^^
  File "/home/gyuri/venv/lib/python3.12/site-packages/flask/app.py", line 865, in dispatch_request
    return self.ensure_sync(self.view_functions[rule.endpoint])(**view_args)  # type: ignore[no-any-return]
           ^^^^^^^^^^^^^^^^^^^^^^^^^^^^^^^^^^^^^^^^^^^^^^^^^^^^^^^^^^^^^^^^^
TypeError: ImageD.index() missing 1 required positional argument: 'self'
2024-09-14 14:53:43,283 - werkzeug - INFO - 127.0.0.1 - - [14/Sep/2024 14:53:43] "[35m[1mGET / HTTP/1.1[0m" 500 -
2024-09-14 14:53:52,066 - Image_detailer.app - ERROR - Exception on / [GET]
Traceback (most recent call last):
  File "/home/gyuri/venv/lib/python3.12/site-packages/flask/app.py", line 1473, in wsgi_app
    response = self.full_dispatch_request()
               ^^^^^^^^^^^^^^^^^^^^^^^^^^^^
  File "/home/gyuri/venv/lib/python3.12/site-packages/flask/app.py", line 882, in full_dispatch_request
    rv = self.handle_user_exception(e)
         ^^^^^^^^^^^^^^^^^^^^^^^^^^^^^
  File "/home/gyuri/venv/lib/python3.12/site-packages/flask/app.py", line 880, in full_dispatch_request
    rv = self.dispatch_request()
         ^^^^^^^^^^^^^^^^^^^^^^^
  File "/home/gyuri/venv/lib/python3.12/site-packages/flask/app.py", line 865, in dispatch_request
    return self.ensure_sync(self.view_functions[rule.endpoint])(**view_args)  # type: ignore[no-any-return]
           ^^^^^^^^^^^^^^^^^^^^^^^^^^^^^^^^^^^^^^^^^^^^^^^^^^^^^^^^^^^^^^^^^
TypeError: ImageD.index() missing 1 required positional argument: 'self'
2024-09-14 14:53:52,067 - werkzeug - INFO - 127.0.0.1 - - [14/Sep/2024 14:53:52] "[35m[1mGET / HTTP/1.1[0m" 500 -
2024-09-14 14:54:13,692 - Image_detailer.app - ERROR - Exception on /shutdown [POST]
Traceback (most recent call last):
  File "/home/gyuri/venv/lib/python3.12/site-packages/flask/app.py", line 1473, in wsgi_app
    response = self.full_dispatch_request()
               ^^^^^^^^^^^^^^^^^^^^^^^^^^^^
  File "/home/gyuri/venv/lib/python3.12/site-packages/flask/app.py", line 882, in full_dispatch_request
    rv = self.handle_user_exception(e)
         ^^^^^^^^^^^^^^^^^^^^^^^^^^^^^
  File "/home/gyuri/venv/lib/python3.12/site-packages/flask/app.py", line 880, in full_dispatch_request
    rv = self.dispatch_request()
         ^^^^^^^^^^^^^^^^^^^^^^^
  File "/home/gyuri/venv/lib/python3.12/site-packages/flask/app.py", line 865, in dispatch_request
    return self.ensure_sync(self.view_functions[rule.endpoint])(**view_args)  # type: ignore[no-any-return]
           ^^^^^^^^^^^^^^^^^^^^^^^^^^^^^^^^^^^^^^^^^^^^^^^^^^^^^^^^^^^^^^^^^
TypeError: ImageD.shutdown() missing 1 required positional argument: 'self'
2024-09-14 14:54:13,693 - werkzeug - INFO - 127.0.0.1 - - [14/Sep/2024 14:54:13] "[35m[1mPOST /shutdown HTTP/1.1[0m" 500 -
2024-09-14 14:54:13,694 - logs - INFO - Server shutdown request sent.
2024-09-14 14:54:13,694 - logs - INFO - Server thread joined successfully.
2024-09-14 14:54:22,794 - logs - INFO - Server started.
2024-09-14 14:54:22,804 - werkzeug - INFO - [31m[1mWARNING: This is a development server. Do not use it in a production deployment. Use a production WSGI server instead.[0m
 * Running on http://127.0.0.1:5000
2024-09-14 14:54:22,804 - werkzeug - INFO - [33mPress CTRL+C to quit[0m
2024-09-14 14:54:27,650 - Image_detailer.app - ERROR - Exception on / [GET]
Traceback (most recent call last):
  File "/home/gyuri/venv/lib/python3.12/site-packages/flask/app.py", line 1473, in wsgi_app
    response = self.full_dispatch_request()
               ^^^^^^^^^^^^^^^^^^^^^^^^^^^^
  File "/home/gyuri/venv/lib/python3.12/site-packages/flask/app.py", line 882, in full_dispatch_request
    rv = self.handle_user_exception(e)
         ^^^^^^^^^^^^^^^^^^^^^^^^^^^^^
  File "/home/gyuri/venv/lib/python3.12/site-packages/flask/app.py", line 880, in full_dispatch_request
    rv = self.dispatch_request()
         ^^^^^^^^^^^^^^^^^^^^^^^
  File "/home/gyuri/venv/lib/python3.12/site-packages/flask/app.py", line 865, in dispatch_request
    return self.ensure_sync(self.view_functions[rule.endpoint])(**view_args)  # type: ignore[no-any-return]
           ^^^^^^^^^^^^^^^^^^^^^^^^^^^^^^^^^^^^^^^^^^^^^^^^^^^^^^^^^^^^^^^^^
TypeError: ImageD.index() missing 1 required positional argument: 'self'
2024-09-14 14:54:27,655 - werkzeug - INFO - 127.0.0.1 - - [14/Sep/2024 14:54:27] "[35m[1mGET / HTTP/1.1[0m" 500 -
2024-09-14 14:54:27,798 - werkzeug - INFO - 127.0.0.1 - - [14/Sep/2024 14:54:27] "[33mGET /favicon.ico HTTP/1.1[0m" 404 -
2024-09-14 15:03:55,918 - logs - INFO - Server started.
2024-09-14 15:03:55,922 - werkzeug - INFO - [31m[1mWARNING: This is a development server. Do not use it in a production deployment. Use a production WSGI server instead.[0m
 * Running on http://127.0.0.1:5000
2024-09-14 15:03:55,923 - werkzeug - INFO - [33mPress CTRL+C to quit[0m
2024-09-14 15:03:58,933 - werkzeug - INFO - 127.0.0.1 - - [14/Sep/2024 15:03:58] "GET / HTTP/1.1" 200 -
2024-09-14 15:03:58,973 - werkzeug - INFO - 127.0.0.1 - - [14/Sep/2024 15:03:58] "GET /static/styles.css HTTP/1.1" 200 -
2024-09-14 15:04:00,301 - Image_detailer.app - ERROR - Exception on /vulnerabilities [GET]
Traceback (most recent call last):
  File "/home/gyuri/venv/lib/python3.12/site-packages/flask/app.py", line 1473, in wsgi_app
    response = self.full_dispatch_request()
               ^^^^^^^^^^^^^^^^^^^^^^^^^^^^
  File "/home/gyuri/venv/lib/python3.12/site-packages/flask/app.py", line 882, in full_dispatch_request
    rv = self.handle_user_exception(e)
         ^^^^^^^^^^^^^^^^^^^^^^^^^^^^^
  File "/home/gyuri/venv/lib/python3.12/site-packages/flask/app.py", line 880, in full_dispatch_request
    rv = self.dispatch_request()
         ^^^^^^^^^^^^^^^^^^^^^^^
  File "/home/gyuri/venv/lib/python3.12/site-packages/flask/app.py", line 865, in dispatch_request
    return self.ensure_sync(self.view_functions[rule.endpoint])(**view_args)  # type: ignore[no-any-return]
           ^^^^^^^^^^^^^^^^^^^^^^^^^^^^^^^^^^^^^^^^^^^^^^^^^^^^^^^^^^^^^^^^^
  File "/home/gyuri/Docking/DockerManager/Image_detailer/app.py", line 570, in vulnerabilities
    available_images = ImageD.get_docker_images()  # Get the list of available Docker images
                       ^^^^^^^^^^^^^^^^^^^^^^^^^^
TypeError: ImageD.get_docker_images() missing 1 required positional argument: 'self'
2024-09-14 15:04:00,302 - werkzeug - INFO - 127.0.0.1 - - [14/Sep/2024 15:04:00] "[35m[1mGET /vulnerabilities HTTP/1.1[0m" 500 -
2024-09-14 15:05:00,754 - Image_detailer.app - ERROR - Exception on /vulnerabilities [GET]
Traceback (most recent call last):
  File "/home/gyuri/venv/lib/python3.12/site-packages/flask/app.py", line 1473, in wsgi_app
    response = self.full_dispatch_request()
               ^^^^^^^^^^^^^^^^^^^^^^^^^^^^
  File "/home/gyuri/venv/lib/python3.12/site-packages/flask/app.py", line 882, in full_dispatch_request
    rv = self.handle_user_exception(e)
         ^^^^^^^^^^^^^^^^^^^^^^^^^^^^^
  File "/home/gyuri/venv/lib/python3.12/site-packages/flask/app.py", line 880, in full_dispatch_request
    rv = self.dispatch_request()
         ^^^^^^^^^^^^^^^^^^^^^^^
  File "/home/gyuri/venv/lib/python3.12/site-packages/flask/app.py", line 865, in dispatch_request
    return self.ensure_sync(self.view_functions[rule.endpoint])(**view_args)  # type: ignore[no-any-return]
           ^^^^^^^^^^^^^^^^^^^^^^^^^^^^^^^^^^^^^^^^^^^^^^^^^^^^^^^^^^^^^^^^^
  File "/home/gyuri/Docking/DockerManager/Image_detailer/app.py", line 570, in vulnerabilities
    available_images = ImageD.get_docker_images()  # Get the list of available Docker images
                       ^^^^^^^^^^^^^^^^^^^^^^^^^^
TypeError: ImageD.get_docker_images() missing 1 required positional argument: 'self'
2024-09-14 15:05:00,759 - werkzeug - INFO - 127.0.0.1 - - [14/Sep/2024 15:05:00] "[35m[1mGET /vulnerabilities HTTP/1.1[0m" 500 -
2024-09-14 15:05:01,814 - Image_detailer.app - ERROR - Exception on /vulnerabilities [GET]
Traceback (most recent call last):
  File "/home/gyuri/venv/lib/python3.12/site-packages/flask/app.py", line 1473, in wsgi_app
    response = self.full_dispatch_request()
               ^^^^^^^^^^^^^^^^^^^^^^^^^^^^
  File "/home/gyuri/venv/lib/python3.12/site-packages/flask/app.py", line 882, in full_dispatch_request
    rv = self.handle_user_exception(e)
         ^^^^^^^^^^^^^^^^^^^^^^^^^^^^^
  File "/home/gyuri/venv/lib/python3.12/site-packages/flask/app.py", line 880, in full_dispatch_request
    rv = self.dispatch_request()
         ^^^^^^^^^^^^^^^^^^^^^^^
  File "/home/gyuri/venv/lib/python3.12/site-packages/flask/app.py", line 865, in dispatch_request
    return self.ensure_sync(self.view_functions[rule.endpoint])(**view_args)  # type: ignore[no-any-return]
           ^^^^^^^^^^^^^^^^^^^^^^^^^^^^^^^^^^^^^^^^^^^^^^^^^^^^^^^^^^^^^^^^^
  File "/home/gyuri/Docking/DockerManager/Image_detailer/app.py", line 570, in vulnerabilities
    available_images = ImageD.get_docker_images()  # Get the list of available Docker images
                       ^^^^^^^^^^^^^^^^^^^^^^^^^^
TypeError: ImageD.get_docker_images() missing 1 required positional argument: 'self'
2024-09-14 15:05:01,817 - werkzeug - INFO - 127.0.0.1 - - [14/Sep/2024 15:05:01] "[35m[1mGET /vulnerabilities HTTP/1.1[0m" 500 -
2024-09-14 15:05:02,172 - Image_detailer.app - ERROR - Exception on /vulnerabilities [GET]
Traceback (most recent call last):
  File "/home/gyuri/venv/lib/python3.12/site-packages/flask/app.py", line 1473, in wsgi_app
    response = self.full_dispatch_request()
               ^^^^^^^^^^^^^^^^^^^^^^^^^^^^
  File "/home/gyuri/venv/lib/python3.12/site-packages/flask/app.py", line 882, in full_dispatch_request
    rv = self.handle_user_exception(e)
         ^^^^^^^^^^^^^^^^^^^^^^^^^^^^^
  File "/home/gyuri/venv/lib/python3.12/site-packages/flask/app.py", line 880, in full_dispatch_request
    rv = self.dispatch_request()
         ^^^^^^^^^^^^^^^^^^^^^^^
  File "/home/gyuri/venv/lib/python3.12/site-packages/flask/app.py", line 865, in dispatch_request
    return self.ensure_sync(self.view_functions[rule.endpoint])(**view_args)  # type: ignore[no-any-return]
           ^^^^^^^^^^^^^^^^^^^^^^^^^^^^^^^^^^^^^^^^^^^^^^^^^^^^^^^^^^^^^^^^^
  File "/home/gyuri/Docking/DockerManager/Image_detailer/app.py", line 570, in vulnerabilities
    available_images = ImageD.get_docker_images()  # Get the list of available Docker images
                       ^^^^^^^^^^^^^^^^^^^^^^^^^^
TypeError: ImageD.get_docker_images() missing 1 required positional argument: 'self'
2024-09-14 15:05:02,173 - werkzeug - INFO - 127.0.0.1 - - [14/Sep/2024 15:05:02] "[35m[1mGET /vulnerabilities HTTP/1.1[0m" 500 -
2024-09-14 15:05:02,492 - Image_detailer.app - ERROR - Exception on /vulnerabilities [GET]
Traceback (most recent call last):
  File "/home/gyuri/venv/lib/python3.12/site-packages/flask/app.py", line 1473, in wsgi_app
    response = self.full_dispatch_request()
               ^^^^^^^^^^^^^^^^^^^^^^^^^^^^
  File "/home/gyuri/venv/lib/python3.12/site-packages/flask/app.py", line 882, in full_dispatch_request
    rv = self.handle_user_exception(e)
         ^^^^^^^^^^^^^^^^^^^^^^^^^^^^^
  File "/home/gyuri/venv/lib/python3.12/site-packages/flask/app.py", line 880, in full_dispatch_request
    rv = self.dispatch_request()
         ^^^^^^^^^^^^^^^^^^^^^^^
  File "/home/gyuri/venv/lib/python3.12/site-packages/flask/app.py", line 865, in dispatch_request
    return self.ensure_sync(self.view_functions[rule.endpoint])(**view_args)  # type: ignore[no-any-return]
           ^^^^^^^^^^^^^^^^^^^^^^^^^^^^^^^^^^^^^^^^^^^^^^^^^^^^^^^^^^^^^^^^^
  File "/home/gyuri/Docking/DockerManager/Image_detailer/app.py", line 570, in vulnerabilities
    available_images = ImageD.get_docker_images()  # Get the list of available Docker images
                       ^^^^^^^^^^^^^^^^^^^^^^^^^^
TypeError: ImageD.get_docker_images() missing 1 required positional argument: 'self'
2024-09-14 15:05:02,494 - werkzeug - INFO - 127.0.0.1 - - [14/Sep/2024 15:05:02] "[35m[1mGET /vulnerabilities HTTP/1.1[0m" 500 -
2024-09-14 15:05:02,824 - Image_detailer.app - ERROR - Exception on /vulnerabilities [GET]
Traceback (most recent call last):
  File "/home/gyuri/venv/lib/python3.12/site-packages/flask/app.py", line 1473, in wsgi_app
    response = self.full_dispatch_request()
               ^^^^^^^^^^^^^^^^^^^^^^^^^^^^
  File "/home/gyuri/venv/lib/python3.12/site-packages/flask/app.py", line 882, in full_dispatch_request
    rv = self.handle_user_exception(e)
         ^^^^^^^^^^^^^^^^^^^^^^^^^^^^^
  File "/home/gyuri/venv/lib/python3.12/site-packages/flask/app.py", line 880, in full_dispatch_request
    rv = self.dispatch_request()
         ^^^^^^^^^^^^^^^^^^^^^^^
  File "/home/gyuri/venv/lib/python3.12/site-packages/flask/app.py", line 865, in dispatch_request
    return self.ensure_sync(self.view_functions[rule.endpoint])(**view_args)  # type: ignore[no-any-return]
           ^^^^^^^^^^^^^^^^^^^^^^^^^^^^^^^^^^^^^^^^^^^^^^^^^^^^^^^^^^^^^^^^^
  File "/home/gyuri/Docking/DockerManager/Image_detailer/app.py", line 570, in vulnerabilities
    available_images = ImageD.get_docker_images()  # Get the list of available Docker images
                       ^^^^^^^^^^^^^^^^^^^^^^^^^^
TypeError: ImageD.get_docker_images() missing 1 required positional argument: 'self'
2024-09-14 15:05:02,825 - werkzeug - INFO - 127.0.0.1 - - [14/Sep/2024 15:05:02] "[35m[1mGET /vulnerabilities HTTP/1.1[0m" 500 -
2024-09-14 15:05:08,280 - Image_detailer.app - ERROR - Exception on /shutdown [POST]
Traceback (most recent call last):
  File "/home/gyuri/venv/lib/python3.12/site-packages/flask/app.py", line 1473, in wsgi_app
    response = self.full_dispatch_request()
               ^^^^^^^^^^^^^^^^^^^^^^^^^^^^
  File "/home/gyuri/venv/lib/python3.12/site-packages/flask/app.py", line 882, in full_dispatch_request
    rv = self.handle_user_exception(e)
         ^^^^^^^^^^^^^^^^^^^^^^^^^^^^^
  File "/home/gyuri/venv/lib/python3.12/site-packages/flask/app.py", line 880, in full_dispatch_request
    rv = self.dispatch_request()
         ^^^^^^^^^^^^^^^^^^^^^^^
  File "/home/gyuri/venv/lib/python3.12/site-packages/flask/app.py", line 865, in dispatch_request
    return self.ensure_sync(self.view_functions[rule.endpoint])(**view_args)  # type: ignore[no-any-return]
           ^^^^^^^^^^^^^^^^^^^^^^^^^^^^^^^^^^^^^^^^^^^^^^^^^^^^^^^^^^^^^^^^^
TypeError: shutdown() missing 1 required positional argument: 'self'
2024-09-14 15:05:08,281 - werkzeug - INFO - 127.0.0.1 - - [14/Sep/2024 15:05:08] "[35m[1mPOST /shutdown HTTP/1.1[0m" 500 -
2024-09-14 15:05:08,282 - logs - INFO - Server shutdown request sent.
2024-09-14 15:05:08,282 - logs - INFO - Server thread joined successfully.
2024-09-14 15:05:12,791 - logs - INFO - Server started.
2024-09-14 15:05:12,798 - werkzeug - INFO - [31m[1mWARNING: This is a development server. Do not use it in a production deployment. Use a production WSGI server instead.[0m
 * Running on http://127.0.0.1:5000
2024-09-14 15:05:12,798 - werkzeug - INFO - [33mPress CTRL+C to quit[0m
2024-09-14 15:05:14,716 - werkzeug - INFO - 127.0.0.1 - - [14/Sep/2024 15:05:14] "GET /vulnerabilities HTTP/1.1" 200 -
2024-09-14 15:05:14,741 - werkzeug - INFO - 127.0.0.1 - - [14/Sep/2024 15:05:14] "[36mGET /static/styles.css HTTP/1.1[0m" 304 -
2024-09-14 15:05:46,762 - werkzeug - INFO - 127.0.0.1 - - [14/Sep/2024 15:05:46] "POST /vulnerabilities HTTP/1.1" 200 -
2024-09-14 15:05:46,828 - werkzeug - INFO - 127.0.0.1 - - [14/Sep/2024 15:05:46] "[36mGET /static/styles.css HTTP/1.1[0m" 304 -
2024-09-14 15:06:25,873 - werkzeug - INFO - 127.0.0.1 - - [14/Sep/2024 15:06:25] "GET / HTTP/1.1" 200 -
2024-09-14 15:06:25,902 - werkzeug - INFO - 127.0.0.1 - - [14/Sep/2024 15:06:25] "[36mGET /static/styles.css HTTP/1.1[0m" 304 -
2024-09-14 15:06:27,477 - werkzeug - INFO - 127.0.0.1 - - [14/Sep/2024 15:06:27] "GET /images HTTP/1.1" 200 -
2024-09-14 15:06:27,498 - werkzeug - INFO - 127.0.0.1 - - [14/Sep/2024 15:06:27] "[36mGET /static/styles.css HTTP/1.1[0m" 304 -
2024-09-14 15:06:28,406 - werkzeug - INFO - 127.0.0.1 - - [14/Sep/2024 15:06:28] "GET /image_size_breakdown HTTP/1.1" 200 -
2024-09-14 15:06:28,429 - werkzeug - INFO - 127.0.0.1 - - [14/Sep/2024 15:06:28] "[36mGET /static/styles.css HTTP/1.1[0m" 304 -
2024-09-14 15:06:30,538 - werkzeug - INFO - 127.0.0.1 - - [14/Sep/2024 15:06:30] "GET /environment_variables HTTP/1.1" 200 -
2024-09-14 15:06:30,561 - werkzeug - INFO - 127.0.0.1 - - [14/Sep/2024 15:06:30] "[36mGET /static/styles.css HTTP/1.1[0m" 304 -
2024-09-14 15:06:32,034 - Image_detailer.app - ERROR - Exception on /layer_comparison [GET]
Traceback (most recent call last):
  File "/home/gyuri/venv/lib/python3.12/site-packages/flask/app.py", line 1473, in wsgi_app
    response = self.full_dispatch_request()
               ^^^^^^^^^^^^^^^^^^^^^^^^^^^^
  File "/home/gyuri/venv/lib/python3.12/site-packages/flask/app.py", line 882, in full_dispatch_request
    rv = self.handle_user_exception(e)
         ^^^^^^^^^^^^^^^^^^^^^^^^^^^^^
  File "/home/gyuri/venv/lib/python3.12/site-packages/flask/app.py", line 880, in full_dispatch_request
    rv = self.dispatch_request()
         ^^^^^^^^^^^^^^^^^^^^^^^
  File "/home/gyuri/venv/lib/python3.12/site-packages/flask/app.py", line 865, in dispatch_request
    return self.ensure_sync(self.view_functions[rule.endpoint])(**view_args)  # type: ignore[no-any-return]
           ^^^^^^^^^^^^^^^^^^^^^^^^^^^^^^^^^^^^^^^^^^^^^^^^^^^^^^^^^^^^^^^^^
TypeError: layer_comparison() missing 1 required positional argument: 'self'
2024-09-14 15:06:32,036 - werkzeug - INFO - 127.0.0.1 - - [14/Sep/2024 15:06:32] "[35m[1mGET /layer_comparison HTTP/1.1[0m" 500 -
2024-09-14 15:07:14,879 - Image_detailer.app - ERROR - Exception on /layer_comparison [GET]
Traceback (most recent call last):
  File "/home/gyuri/venv/lib/python3.12/site-packages/flask/app.py", line 1473, in wsgi_app
    response = self.full_dispatch_request()
               ^^^^^^^^^^^^^^^^^^^^^^^^^^^^
  File "/home/gyuri/venv/lib/python3.12/site-packages/flask/app.py", line 882, in full_dispatch_request
    rv = self.handle_user_exception(e)
         ^^^^^^^^^^^^^^^^^^^^^^^^^^^^^
  File "/home/gyuri/venv/lib/python3.12/site-packages/flask/app.py", line 880, in full_dispatch_request
    rv = self.dispatch_request()
         ^^^^^^^^^^^^^^^^^^^^^^^
  File "/home/gyuri/venv/lib/python3.12/site-packages/flask/app.py", line 865, in dispatch_request
    return self.ensure_sync(self.view_functions[rule.endpoint])(**view_args)  # type: ignore[no-any-return]
           ^^^^^^^^^^^^^^^^^^^^^^^^^^^^^^^^^^^^^^^^^^^^^^^^^^^^^^^^^^^^^^^^^
TypeError: layer_comparison() missing 1 required positional argument: 'self'
2024-09-14 15:07:14,881 - werkzeug - INFO - 127.0.0.1 - - [14/Sep/2024 15:07:14] "[35m[1mGET /layer_comparison HTTP/1.1[0m" 500 -
2024-09-14 15:07:15,583 - Image_detailer.app - ERROR - Exception on /layer_comparison [GET]
Traceback (most recent call last):
  File "/home/gyuri/venv/lib/python3.12/site-packages/flask/app.py", line 1473, in wsgi_app
    response = self.full_dispatch_request()
               ^^^^^^^^^^^^^^^^^^^^^^^^^^^^
  File "/home/gyuri/venv/lib/python3.12/site-packages/flask/app.py", line 882, in full_dispatch_request
    rv = self.handle_user_exception(e)
         ^^^^^^^^^^^^^^^^^^^^^^^^^^^^^
  File "/home/gyuri/venv/lib/python3.12/site-packages/flask/app.py", line 880, in full_dispatch_request
    rv = self.dispatch_request()
         ^^^^^^^^^^^^^^^^^^^^^^^
  File "/home/gyuri/venv/lib/python3.12/site-packages/flask/app.py", line 865, in dispatch_request
    return self.ensure_sync(self.view_functions[rule.endpoint])(**view_args)  # type: ignore[no-any-return]
           ^^^^^^^^^^^^^^^^^^^^^^^^^^^^^^^^^^^^^^^^^^^^^^^^^^^^^^^^^^^^^^^^^
TypeError: layer_comparison() missing 1 required positional argument: 'self'
2024-09-14 15:07:15,583 - werkzeug - INFO - 127.0.0.1 - - [14/Sep/2024 15:07:15] "[35m[1mGET /layer_comparison HTTP/1.1[0m" 500 -
2024-09-14 15:07:15,774 - Image_detailer.app - ERROR - Exception on /layer_comparison [GET]
Traceback (most recent call last):
  File "/home/gyuri/venv/lib/python3.12/site-packages/flask/app.py", line 1473, in wsgi_app
    response = self.full_dispatch_request()
               ^^^^^^^^^^^^^^^^^^^^^^^^^^^^
  File "/home/gyuri/venv/lib/python3.12/site-packages/flask/app.py", line 882, in full_dispatch_request
    rv = self.handle_user_exception(e)
         ^^^^^^^^^^^^^^^^^^^^^^^^^^^^^
  File "/home/gyuri/venv/lib/python3.12/site-packages/flask/app.py", line 880, in full_dispatch_request
    rv = self.dispatch_request()
         ^^^^^^^^^^^^^^^^^^^^^^^
  File "/home/gyuri/venv/lib/python3.12/site-packages/flask/app.py", line 865, in dispatch_request
    return self.ensure_sync(self.view_functions[rule.endpoint])(**view_args)  # type: ignore[no-any-return]
           ^^^^^^^^^^^^^^^^^^^^^^^^^^^^^^^^^^^^^^^^^^^^^^^^^^^^^^^^^^^^^^^^^
TypeError: layer_comparison() missing 1 required positional argument: 'self'
2024-09-14 15:07:15,775 - werkzeug - INFO - 127.0.0.1 - - [14/Sep/2024 15:07:15] "[35m[1mGET /layer_comparison HTTP/1.1[0m" 500 -
2024-09-14 15:07:15,958 - Image_detailer.app - ERROR - Exception on /layer_comparison [GET]
Traceback (most recent call last):
  File "/home/gyuri/venv/lib/python3.12/site-packages/flask/app.py", line 1473, in wsgi_app
    response = self.full_dispatch_request()
               ^^^^^^^^^^^^^^^^^^^^^^^^^^^^
  File "/home/gyuri/venv/lib/python3.12/site-packages/flask/app.py", line 882, in full_dispatch_request
    rv = self.handle_user_exception(e)
         ^^^^^^^^^^^^^^^^^^^^^^^^^^^^^
  File "/home/gyuri/venv/lib/python3.12/site-packages/flask/app.py", line 880, in full_dispatch_request
    rv = self.dispatch_request()
         ^^^^^^^^^^^^^^^^^^^^^^^
  File "/home/gyuri/venv/lib/python3.12/site-packages/flask/app.py", line 865, in dispatch_request
    return self.ensure_sync(self.view_functions[rule.endpoint])(**view_args)  # type: ignore[no-any-return]
           ^^^^^^^^^^^^^^^^^^^^^^^^^^^^^^^^^^^^^^^^^^^^^^^^^^^^^^^^^^^^^^^^^
TypeError: layer_comparison() missing 1 required positional argument: 'self'
2024-09-14 15:07:15,959 - werkzeug - INFO - 127.0.0.1 - - [14/Sep/2024 15:07:15] "[35m[1mGET /layer_comparison HTTP/1.1[0m" 500 -
2024-09-14 15:07:17,561 - Image_detailer.app - ERROR - Exception on /layer_comparison [GET]
Traceback (most recent call last):
  File "/home/gyuri/venv/lib/python3.12/site-packages/flask/app.py", line 1473, in wsgi_app
    response = self.full_dispatch_request()
               ^^^^^^^^^^^^^^^^^^^^^^^^^^^^
  File "/home/gyuri/venv/lib/python3.12/site-packages/flask/app.py", line 882, in full_dispatch_request
    rv = self.handle_user_exception(e)
         ^^^^^^^^^^^^^^^^^^^^^^^^^^^^^
  File "/home/gyuri/venv/lib/python3.12/site-packages/flask/app.py", line 880, in full_dispatch_request
    rv = self.dispatch_request()
         ^^^^^^^^^^^^^^^^^^^^^^^
  File "/home/gyuri/venv/lib/python3.12/site-packages/flask/app.py", line 865, in dispatch_request
    return self.ensure_sync(self.view_functions[rule.endpoint])(**view_args)  # type: ignore[no-any-return]
           ^^^^^^^^^^^^^^^^^^^^^^^^^^^^^^^^^^^^^^^^^^^^^^^^^^^^^^^^^^^^^^^^^
TypeError: layer_comparison() missing 1 required positional argument: 'self'
2024-09-14 15:07:17,562 - werkzeug - INFO - 127.0.0.1 - - [14/Sep/2024 15:07:17] "[35m[1mGET /layer_comparison HTTP/1.1[0m" 500 -
2024-09-14 15:07:22,860 - Image_detailer.app - ERROR - Exception on /shutdown [POST]
Traceback (most recent call last):
  File "/home/gyuri/venv/lib/python3.12/site-packages/flask/app.py", line 1473, in wsgi_app
    response = self.full_dispatch_request()
               ^^^^^^^^^^^^^^^^^^^^^^^^^^^^
  File "/home/gyuri/venv/lib/python3.12/site-packages/flask/app.py", line 882, in full_dispatch_request
    rv = self.handle_user_exception(e)
         ^^^^^^^^^^^^^^^^^^^^^^^^^^^^^
  File "/home/gyuri/venv/lib/python3.12/site-packages/flask/app.py", line 880, in full_dispatch_request
    rv = self.dispatch_request()
         ^^^^^^^^^^^^^^^^^^^^^^^
  File "/home/gyuri/venv/lib/python3.12/site-packages/flask/app.py", line 865, in dispatch_request
    return self.ensure_sync(self.view_functions[rule.endpoint])(**view_args)  # type: ignore[no-any-return]
           ^^^^^^^^^^^^^^^^^^^^^^^^^^^^^^^^^^^^^^^^^^^^^^^^^^^^^^^^^^^^^^^^^
  File "/home/gyuri/Docking/DockerManager/Image_detailer/app.py", line 145, in shutdown
    raise RuntimeError('Not running with the Werkzeug Server')
RuntimeError: Not running with the Werkzeug Server
2024-09-14 15:07:22,862 - werkzeug - INFO - 127.0.0.1 - - [14/Sep/2024 15:07:22] "[35m[1mPOST /shutdown HTTP/1.1[0m" 500 -
2024-09-14 15:07:22,863 - logs - INFO - Server shutdown request sent.
2024-09-14 15:07:22,863 - logs - INFO - Server thread joined successfully.
2024-09-14 15:07:33,842 - logs - INFO - Server started.
2024-09-14 15:07:33,847 - werkzeug - INFO - [31m[1mWARNING: This is a development server. Do not use it in a production deployment. Use a production WSGI server instead.[0m
 * Running on http://127.0.0.1:5000
2024-09-14 15:07:33,847 - werkzeug - INFO - [33mPress CTRL+C to quit[0m
2024-09-14 15:07:36,603 - werkzeug - INFO - 127.0.0.1 - - [14/Sep/2024 15:07:36] "GET /layer_comparison HTTP/1.1" 200 -
2024-09-14 15:07:36,629 - werkzeug - INFO - 127.0.0.1 - - [14/Sep/2024 15:07:36] "[36mGET /static/styles.css HTTP/1.1[0m" 304 -
2024-09-14 15:07:50,242 - werkzeug - INFO - 127.0.0.1 - - [14/Sep/2024 15:07:50] "GET /interactive_visualizations HTTP/1.1" 200 -
2024-09-14 15:07:50,263 - werkzeug - INFO - 127.0.0.1 - - [14/Sep/2024 15:07:50] "[36mGET /static/styles.css HTTP/1.1[0m" 304 -
2024-09-14 15:07:51,528 - werkzeug - INFO - 127.0.0.1 - - [14/Sep/2024 15:07:51] "GET /logs_build_info HTTP/1.1" 200 -
2024-09-14 15:07:51,549 - werkzeug - INFO - 127.0.0.1 - - [14/Sep/2024 15:07:51] "[36mGET /static/styles.css HTTP/1.1[0m" 304 -
2024-09-14 15:07:52,226 - Image_detailer.app - ERROR - Exception on /image_metadata [GET]
Traceback (most recent call last):
  File "/home/gyuri/venv/lib/python3.12/site-packages/flask/app.py", line 1473, in wsgi_app
    response = self.full_dispatch_request()
               ^^^^^^^^^^^^^^^^^^^^^^^^^^^^
  File "/home/gyuri/venv/lib/python3.12/site-packages/flask/app.py", line 882, in full_dispatch_request
    rv = self.handle_user_exception(e)
         ^^^^^^^^^^^^^^^^^^^^^^^^^^^^^
  File "/home/gyuri/venv/lib/python3.12/site-packages/flask/app.py", line 880, in full_dispatch_request
    rv = self.dispatch_request()
         ^^^^^^^^^^^^^^^^^^^^^^^
  File "/home/gyuri/venv/lib/python3.12/site-packages/flask/app.py", line 865, in dispatch_request
    return self.ensure_sync(self.view_functions[rule.endpoint])(**view_args)  # type: ignore[no-any-return]
           ^^^^^^^^^^^^^^^^^^^^^^^^^^^^^^^^^^^^^^^^^^^^^^^^^^^^^^^^^^^^^^^^^
TypeError: image_metadata() missing 1 required positional argument: 'self'
2024-09-14 15:07:52,229 - werkzeug - INFO - 127.0.0.1 - - [14/Sep/2024 15:07:52] "[35m[1mGET /image_metadata HTTP/1.1[0m" 500 -
2024-09-14 15:08:26,659 - logs - INFO - Listing all images.
2024-09-14 15:08:30,252 - logs - INFO - Container started from image 'sha256:edbfe74c41f8a3501ce542e137cf28ea04dd03e6df8c9d66519b6ad761c2598a'. Container ID: d04e138fa0f8f8e9811efb7b794e810a3a19d8a997a72a59c423153cfbb599df
2024-09-14 15:08:30,252 - logs - INFO - Opening shell for container with ID: d04e138fa0f8f8e9811efb7b794e810a3a19d8a997a72a59c423153cfbb599df
2024-09-14 15:10:29,191 - Image_detailer.app - ERROR - Exception on /shutdown [POST]
Traceback (most recent call last):
  File "/home/gyuri/venv/lib/python3.12/site-packages/flask/app.py", line 1473, in wsgi_app
    response = self.full_dispatch_request()
               ^^^^^^^^^^^^^^^^^^^^^^^^^^^^
  File "/home/gyuri/venv/lib/python3.12/site-packages/flask/app.py", line 882, in full_dispatch_request
    rv = self.handle_user_exception(e)
         ^^^^^^^^^^^^^^^^^^^^^^^^^^^^^
  File "/home/gyuri/venv/lib/python3.12/site-packages/flask/app.py", line 880, in full_dispatch_request
    rv = self.dispatch_request()
         ^^^^^^^^^^^^^^^^^^^^^^^
  File "/home/gyuri/venv/lib/python3.12/site-packages/flask/app.py", line 865, in dispatch_request
    return self.ensure_sync(self.view_functions[rule.endpoint])(**view_args)  # type: ignore[no-any-return]
           ^^^^^^^^^^^^^^^^^^^^^^^^^^^^^^^^^^^^^^^^^^^^^^^^^^^^^^^^^^^^^^^^^
  File "/home/gyuri/Docking/DockerManager/Image_detailer/app.py", line 145, in shutdown
    raise RuntimeError('Not running with the Werkzeug Server')
RuntimeError: Not running with the Werkzeug Server
2024-09-14 15:10:29,192 - werkzeug - INFO - 127.0.0.1 - - [14/Sep/2024 15:10:29] "[35m[1mPOST /shutdown HTTP/1.1[0m" 500 -
2024-09-14 15:10:29,193 - logs - INFO - Server shutdown request sent.
2024-09-14 15:10:29,193 - logs - INFO - Server thread joined successfully.
2024-09-14 15:11:23,207 - logs - INFO - Server started.
2024-09-14 15:11:23,212 - werkzeug - INFO - [31m[1mWARNING: This is a development server. Do not use it in a production deployment. Use a production WSGI server instead.[0m
 * Running on http://127.0.0.1:5000
2024-09-14 15:11:23,212 - werkzeug - INFO - [33mPress CTRL+C to quit[0m
2024-09-14 15:11:27,284 - Image_detailer.app - ERROR - Exception on /image_metadata [GET]
Traceback (most recent call last):
  File "/home/gyuri/venv/lib/python3.12/site-packages/flask/app.py", line 1473, in wsgi_app
    response = self.full_dispatch_request()
               ^^^^^^^^^^^^^^^^^^^^^^^^^^^^
  File "/home/gyuri/venv/lib/python3.12/site-packages/flask/app.py", line 882, in full_dispatch_request
    rv = self.handle_user_exception(e)
         ^^^^^^^^^^^^^^^^^^^^^^^^^^^^^
  File "/home/gyuri/venv/lib/python3.12/site-packages/flask/app.py", line 880, in full_dispatch_request
    rv = self.dispatch_request()
         ^^^^^^^^^^^^^^^^^^^^^^^
  File "/home/gyuri/venv/lib/python3.12/site-packages/flask/app.py", line 865, in dispatch_request
    return self.ensure_sync(self.view_functions[rule.endpoint])(**view_args)  # type: ignore[no-any-return]
           ^^^^^^^^^^^^^^^^^^^^^^^^^^^^^^^^^^^^^^^^^^^^^^^^^^^^^^^^^^^^^^^^^
TypeError: image_metadata() missing 1 required positional argument: 'self'
2024-09-14 15:11:27,286 - werkzeug - INFO - 127.0.0.1 - - [14/Sep/2024 15:11:27] "[35m[1mGET /image_metadata HTTP/1.1[0m" 500 -
2024-09-14 15:11:28,325 - Image_detailer.app - ERROR - Exception on /image_metadata [GET]
Traceback (most recent call last):
  File "/home/gyuri/venv/lib/python3.12/site-packages/flask/app.py", line 1473, in wsgi_app
    response = self.full_dispatch_request()
               ^^^^^^^^^^^^^^^^^^^^^^^^^^^^
  File "/home/gyuri/venv/lib/python3.12/site-packages/flask/app.py", line 882, in full_dispatch_request
    rv = self.handle_user_exception(e)
         ^^^^^^^^^^^^^^^^^^^^^^^^^^^^^
  File "/home/gyuri/venv/lib/python3.12/site-packages/flask/app.py", line 880, in full_dispatch_request
    rv = self.dispatch_request()
         ^^^^^^^^^^^^^^^^^^^^^^^
  File "/home/gyuri/venv/lib/python3.12/site-packages/flask/app.py", line 865, in dispatch_request
    return self.ensure_sync(self.view_functions[rule.endpoint])(**view_args)  # type: ignore[no-any-return]
           ^^^^^^^^^^^^^^^^^^^^^^^^^^^^^^^^^^^^^^^^^^^^^^^^^^^^^^^^^^^^^^^^^
TypeError: image_metadata() missing 1 required positional argument: 'self'
2024-09-14 15:11:28,326 - werkzeug - INFO - 127.0.0.1 - - [14/Sep/2024 15:11:28] "[35m[1mGET /image_metadata HTTP/1.1[0m" 500 -
2024-09-14 15:11:28,686 - Image_detailer.app - ERROR - Exception on /image_metadata [GET]
Traceback (most recent call last):
  File "/home/gyuri/venv/lib/python3.12/site-packages/flask/app.py", line 1473, in wsgi_app
    response = self.full_dispatch_request()
               ^^^^^^^^^^^^^^^^^^^^^^^^^^^^
  File "/home/gyuri/venv/lib/python3.12/site-packages/flask/app.py", line 882, in full_dispatch_request
    rv = self.handle_user_exception(e)
         ^^^^^^^^^^^^^^^^^^^^^^^^^^^^^
  File "/home/gyuri/venv/lib/python3.12/site-packages/flask/app.py", line 880, in full_dispatch_request
    rv = self.dispatch_request()
         ^^^^^^^^^^^^^^^^^^^^^^^
  File "/home/gyuri/venv/lib/python3.12/site-packages/flask/app.py", line 865, in dispatch_request
    return self.ensure_sync(self.view_functions[rule.endpoint])(**view_args)  # type: ignore[no-any-return]
           ^^^^^^^^^^^^^^^^^^^^^^^^^^^^^^^^^^^^^^^^^^^^^^^^^^^^^^^^^^^^^^^^^
TypeError: image_metadata() missing 1 required positional argument: 'self'
2024-09-14 15:11:28,688 - werkzeug - INFO - 127.0.0.1 - - [14/Sep/2024 15:11:28] "[35m[1mGET /image_metadata HTTP/1.1[0m" 500 -
2024-09-14 15:11:29,123 - Image_detailer.app - ERROR - Exception on /image_metadata [GET]
Traceback (most recent call last):
  File "/home/gyuri/venv/lib/python3.12/site-packages/flask/app.py", line 1473, in wsgi_app
    response = self.full_dispatch_request()
               ^^^^^^^^^^^^^^^^^^^^^^^^^^^^
  File "/home/gyuri/venv/lib/python3.12/site-packages/flask/app.py", line 882, in full_dispatch_request
    rv = self.handle_user_exception(e)
         ^^^^^^^^^^^^^^^^^^^^^^^^^^^^^
  File "/home/gyuri/venv/lib/python3.12/site-packages/flask/app.py", line 880, in full_dispatch_request
    rv = self.dispatch_request()
         ^^^^^^^^^^^^^^^^^^^^^^^
  File "/home/gyuri/venv/lib/python3.12/site-packages/flask/app.py", line 865, in dispatch_request
    return self.ensure_sync(self.view_functions[rule.endpoint])(**view_args)  # type: ignore[no-any-return]
           ^^^^^^^^^^^^^^^^^^^^^^^^^^^^^^^^^^^^^^^^^^^^^^^^^^^^^^^^^^^^^^^^^
TypeError: image_metadata() missing 1 required positional argument: 'self'
2024-09-14 15:11:29,124 - werkzeug - INFO - 127.0.0.1 - - [14/Sep/2024 15:11:29] "[35m[1mGET /image_metadata HTTP/1.1[0m" 500 -
2024-09-14 15:11:32,275 - Image_detailer.app - ERROR - Exception on /image_metadata [GET]
Traceback (most recent call last):
  File "/home/gyuri/venv/lib/python3.12/site-packages/flask/app.py", line 1473, in wsgi_app
    response = self.full_dispatch_request()
               ^^^^^^^^^^^^^^^^^^^^^^^^^^^^
  File "/home/gyuri/venv/lib/python3.12/site-packages/flask/app.py", line 882, in full_dispatch_request
    rv = self.handle_user_exception(e)
         ^^^^^^^^^^^^^^^^^^^^^^^^^^^^^
  File "/home/gyuri/venv/lib/python3.12/site-packages/flask/app.py", line 880, in full_dispatch_request
    rv = self.dispatch_request()
         ^^^^^^^^^^^^^^^^^^^^^^^
  File "/home/gyuri/venv/lib/python3.12/site-packages/flask/app.py", line 865, in dispatch_request
    return self.ensure_sync(self.view_functions[rule.endpoint])(**view_args)  # type: ignore[no-any-return]
           ^^^^^^^^^^^^^^^^^^^^^^^^^^^^^^^^^^^^^^^^^^^^^^^^^^^^^^^^^^^^^^^^^
TypeError: image_metadata() missing 1 required positional argument: 'self'
2024-09-14 15:11:32,276 - werkzeug - INFO - 127.0.0.1 - - [14/Sep/2024 15:11:32] "[35m[1mGET /image_metadata HTTP/1.1[0m" 500 -
2024-09-14 15:12:13,681 - Image_detailer.app - ERROR - Exception on /shutdown [POST]
Traceback (most recent call last):
  File "/home/gyuri/venv/lib/python3.12/site-packages/flask/app.py", line 1473, in wsgi_app
    response = self.full_dispatch_request()
               ^^^^^^^^^^^^^^^^^^^^^^^^^^^^
  File "/home/gyuri/venv/lib/python3.12/site-packages/flask/app.py", line 882, in full_dispatch_request
    rv = self.handle_user_exception(e)
         ^^^^^^^^^^^^^^^^^^^^^^^^^^^^^
  File "/home/gyuri/venv/lib/python3.12/site-packages/flask/app.py", line 880, in full_dispatch_request
    rv = self.dispatch_request()
         ^^^^^^^^^^^^^^^^^^^^^^^
  File "/home/gyuri/venv/lib/python3.12/site-packages/flask/app.py", line 865, in dispatch_request
    return self.ensure_sync(self.view_functions[rule.endpoint])(**view_args)  # type: ignore[no-any-return]
           ^^^^^^^^^^^^^^^^^^^^^^^^^^^^^^^^^^^^^^^^^^^^^^^^^^^^^^^^^^^^^^^^^
  File "/home/gyuri/Docking/DockerManager/Image_detailer/app.py", line 145, in shutdown
    raise RuntimeError('Not running with the Werkzeug Server')
RuntimeError: Not running with the Werkzeug Server
2024-09-14 15:12:13,682 - werkzeug - INFO - 127.0.0.1 - - [14/Sep/2024 15:12:13] "[35m[1mPOST /shutdown HTTP/1.1[0m" 500 -
2024-09-14 15:12:13,683 - logs - INFO - Server shutdown request sent.
2024-09-14 15:12:13,683 - logs - INFO - Server thread joined successfully.
2024-09-14 15:12:16,872 - logs - INFO - Server started.
2024-09-14 15:12:16,877 - werkzeug - INFO - [31m[1mWARNING: This is a development server. Do not use it in a production deployment. Use a production WSGI server instead.[0m
 * Running on http://127.0.0.1:5000
2024-09-14 15:12:16,877 - werkzeug - INFO - [33mPress CTRL+C to quit[0m
2024-09-14 15:12:18,198 - werkzeug - INFO - 127.0.0.1 - - [14/Sep/2024 15:12:18] "GET /image_metadata HTTP/1.1" 200 -
2024-09-14 15:12:18,242 - werkzeug - INFO - 127.0.0.1 - - [14/Sep/2024 15:12:18] "[36mGET /static/styles.css HTTP/1.1[0m" 304 -
2024-09-14 15:12:22,218 - werkzeug - INFO - 127.0.0.1 - - [14/Sep/2024 15:12:22] "GET /volume_network_info HTTP/1.1" 200 -
2024-09-14 15:12:22,240 - werkzeug - INFO - 127.0.0.1 - - [14/Sep/2024 15:12:22] "[36mGET /static/styles.css HTTP/1.1[0m" 304 -
2024-09-14 15:12:22,987 - werkzeug - INFO - 127.0.0.1 - - [14/Sep/2024 15:12:22] "GET /vulnerabilities HTTP/1.1" 200 -
2024-09-14 15:12:23,006 - werkzeug - INFO - 127.0.0.1 - - [14/Sep/2024 15:12:23] "[36mGET /static/styles.css HTTP/1.1[0m" 304 -
2024-09-14 15:12:24,215 - werkzeug - INFO - 127.0.0.1 - - [14/Sep/2024 15:12:24] "GET /dockerfile_snippets HTTP/1.1" 200 -
2024-09-14 15:12:24,236 - werkzeug - INFO - 127.0.0.1 - - [14/Sep/2024 15:12:24] "[36mGET /static/styles.css HTTP/1.1[0m" 304 -
2024-09-14 15:12:24,946 - werkzeug - INFO - 127.0.0.1 - - [14/Sep/2024 15:12:24] "GET /image_metadata HTTP/1.1" 200 -
2024-09-14 15:12:24,969 - werkzeug - INFO - 127.0.0.1 - - [14/Sep/2024 15:12:24] "[36mGET /static/styles.css HTTP/1.1[0m" 304 -
2024-09-14 15:12:25,511 - werkzeug - INFO - 127.0.0.1 - - [14/Sep/2024 15:12:25] "GET /logs_build_info HTTP/1.1" 200 -
2024-09-14 15:12:25,535 - werkzeug - INFO - 127.0.0.1 - - [14/Sep/2024 15:12:25] "[36mGET /static/styles.css HTTP/1.1[0m" 304 -
2024-09-14 15:12:25,999 - werkzeug - INFO - 127.0.0.1 - - [14/Sep/2024 15:12:25] "GET /logs_build_info HTTP/1.1" 200 -
2024-09-14 15:12:26,022 - werkzeug - INFO - 127.0.0.1 - - [14/Sep/2024 15:12:26] "[36mGET /static/styles.css HTTP/1.1[0m" 304 -
2024-09-14 15:12:26,328 - werkzeug - INFO - 127.0.0.1 - - [14/Sep/2024 15:12:26] "GET /interactive_visualizations HTTP/1.1" 200 -
2024-09-14 15:12:26,349 - werkzeug - INFO - 127.0.0.1 - - [14/Sep/2024 15:12:26] "[36mGET /static/styles.css HTTP/1.1[0m" 304 -
2024-09-14 15:12:26,876 - werkzeug - INFO - 127.0.0.1 - - [14/Sep/2024 15:12:26] "GET /layer_comparison HTTP/1.1" 200 -
2024-09-14 15:12:26,907 - werkzeug - INFO - 127.0.0.1 - - [14/Sep/2024 15:12:26] "[36mGET /static/styles.css HTTP/1.1[0m" 304 -
2024-09-14 15:12:27,393 - werkzeug - INFO - 127.0.0.1 - - [14/Sep/2024 15:12:27] "GET /environment_variables HTTP/1.1" 200 -
2024-09-14 15:12:27,418 - werkzeug - INFO - 127.0.0.1 - - [14/Sep/2024 15:12:27] "[36mGET /static/styles.css HTTP/1.1[0m" 304 -
2024-09-14 15:12:28,008 - werkzeug - INFO - 127.0.0.1 - - [14/Sep/2024 15:12:28] "GET /image_size_breakdown HTTP/1.1" 200 -
2024-09-14 15:12:28,030 - werkzeug - INFO - 127.0.0.1 - - [14/Sep/2024 15:12:28] "[36mGET /static/styles.css HTTP/1.1[0m" 304 -
2024-09-14 15:12:29,426 - werkzeug - INFO - 127.0.0.1 - - [14/Sep/2024 15:12:29] "GET / HTTP/1.1" 200 -
2024-09-14 15:12:29,447 - werkzeug - INFO - 127.0.0.1 - - [14/Sep/2024 15:12:29] "[36mGET /static/styles.css HTTP/1.1[0m" 304 -
2024-09-14 15:12:30,016 - werkzeug - INFO - 127.0.0.1 - - [14/Sep/2024 15:12:30] "GET /images HTTP/1.1" 200 -
2024-09-14 15:12:30,038 - werkzeug - INFO - 127.0.0.1 - - [14/Sep/2024 15:12:30] "[36mGET /static/styles.css HTTP/1.1[0m" 304 -
2024-09-14 15:12:48,546 - Image_detailer.app - ERROR - Exception on /shutdown [POST]
Traceback (most recent call last):
  File "/home/gyuri/venv/lib/python3.12/site-packages/flask/app.py", line 1473, in wsgi_app
    response = self.full_dispatch_request()
               ^^^^^^^^^^^^^^^^^^^^^^^^^^^^
  File "/home/gyuri/venv/lib/python3.12/site-packages/flask/app.py", line 882, in full_dispatch_request
    rv = self.handle_user_exception(e)
         ^^^^^^^^^^^^^^^^^^^^^^^^^^^^^
  File "/home/gyuri/venv/lib/python3.12/site-packages/flask/app.py", line 880, in full_dispatch_request
    rv = self.dispatch_request()
         ^^^^^^^^^^^^^^^^^^^^^^^
  File "/home/gyuri/venv/lib/python3.12/site-packages/flask/app.py", line 865, in dispatch_request
    return self.ensure_sync(self.view_functions[rule.endpoint])(**view_args)  # type: ignore[no-any-return]
           ^^^^^^^^^^^^^^^^^^^^^^^^^^^^^^^^^^^^^^^^^^^^^^^^^^^^^^^^^^^^^^^^^
  File "/home/gyuri/Docking/DockerManager/Image_detailer/app.py", line 145, in shutdown
    raise RuntimeError('Not running with the Werkzeug Server')
RuntimeError: Not running with the Werkzeug Server
2024-09-14 15:12:48,548 - werkzeug - INFO - 127.0.0.1 - - [14/Sep/2024 15:12:48] "[35m[1mPOST /shutdown HTTP/1.1[0m" 500 -
2024-09-14 15:12:48,549 - logs - INFO - Server shutdown request sent.
2024-09-14 15:12:48,549 - logs - INFO - Server thread joined successfully.
